Workbook

Sheet Backup DB Juli 2019
B1: panjang L4 | C1: Seleksi L4 lagi | D1: Seleksi L4 | E1: Panjang | F1: ALL Kandidat L4 | G1: Kandidat L4 | H1: Kandidat L4 | I1: Panjang L2 L3 | J1: Seleksi L2 L3 lagi | K1: Seleksi L2 L3 | L1: ALL Kandidat L2,L3 | M1: Kandidat L2,L3 | N1: Kandidat L2,L3 | O1: ALL Kandidat L1 | P1: Kandidat L1 | Q1: Kandidat L1 | T1: Name | U1: In Folder | V1: Grid | W1: Type | X1: Terminal i | Y1: Terminal i | Z1: Terminal j | AA1: Terminal j | AB1: Zone | AC1: Area | AD1: Out of Service | AE1: Par.no. | AF1: Thermal Rating | AG1: Length | AH1: Derating F. | AI1: Laying | AJ1: Line Model | AK1: Type of Phase Conductors | AL1: Type of Earth Conductors | AM1: Max.Sag, Phase Conductors | AN1: Max.Sag, Ground Wires | AO1: Earth Resistivity | AP1: Transposition | AQ1: Irated(act.) | AR1: Irated | AS1: Z1 | AT1: phiz1 | AU1: R1 | AV1: X1 | AW1: R0 | AX1: X0 | AY1: Ice | AZ1: k0 | BA1: phik0 | BB1: Line Couplings
T2: Name | U2: In Folder | V2: Grid | W2: Type | X2: Terminal i | Y2: Terminal i | Z2: Terminal j | AA2: Terminal j | AB2: Zone | AC2: Area | AD2: Out of Service | AE2: Par.no. | AF2: Thermal Rating | AG2: Length | AH2: Derating F. | AI2: Laying | AJ2: Line Model | AK2: Type of Phase Conductors | AL2: Type of Earth Conductors | AM2: Max.Sag, Phase Conductors | AN2: Max.Sag, Ground Wires | AO2: Earth Resistivity | AP2: Transposition | AQ2: Irated(act.) | AR2: Irated | AS2: Z1 | AT2: phiz1 | AU2: R1 | AV2: X1 | AW2: R0 | AX2: X0 | AY2: Ice | AZ2: k0 | BA2: phik0 | BB2: Line Couplings
D3: =counta(D4:D1375) -> 3 | F3: =counta(F4:F1375) -> 4 | K3: =counta(K4:K1375) -> 3 | L3: =counta(L4:L1375) -> 4 | W3: TypLne,TypTow,TypGeo,TypCabsys | X3: Substation | Z3: Substation | AF3: IntThrating | AG3: km | AK3: TypCon | AL3: TypCon | AM3: m | AN3: m | AO3: Ohmm | AQ3: kA | AR3: kA | AS3: Ohm | AT3: deg | AU3: Ohm | AV3: Ohm | AW3: Ohm | AX3: Ohm | AY3: A | BA3: deg
A4: =COUNTA(C4:Q4)-1 -> 6 | B4: =if(C4="",,AS4) -> 1.647643 | C4: =if(and(D$3>1,E4=PROSES!$D$22),,D4) -> 1MENES-1LBUAN-1 | D4: =if(and(F$3>1,F4=PROSES!$B$22),,F4) -> 1MENES-1LBUAN-1 | E4: =if(F4="",,AS4) -> 1.647643 | F4: =if(G4=H4,,(G4&H4)) -> 1MENES-1LBUAN-1 | G4: =if(Z4=PROSES!$E$29,T4,) | H4: =if(X4=PROSES!$E$29,T4,) -> 1MENES-1LBUAN-1 | I4: =if(J4="",,AS4) | J4: =if(and(K$3>1,R4=PROSES!$C$2),,K4) | K4: =if(and(L$3>1,L4=PROSES!$B$2),,L4) | L4: =if(M4=N4,,(M4&N4)) | M4: =if(Z4=PROSES!$B$3,T4,) | N4: =if(X4=PROSES!$B$3,T4,) | O4: =P4&Q4 -> 1MENES-1LBUAN-1 | P4: =if(Z4=PROSES!$B$1,T4,) | Q4: =if(X4=PROSES!$B$1,T4,) -> 1MENES-1LBUAN-1 | R4: =X4&Z4 -> MENES5PLTU Banten 2 | T4: 1MENES-1LBUAN-1 | U4: region1 | V4: region1 | W4: OHL-150kV-TACSR 2X410mm (2730A) | X4: MENES5 | Y4: I-5 | Z4: PLTU Banten 2 | AA4: I | AD4: 0 | AE4: 1 | AG4: 6.2 | AH4: 1 | AI4: Ground | AJ4: 0 | AM4: 0 | AN4: 0 | AO4: 100 | AP4: 1 | AQ4: 2.73 | AR4: 2.73 | AS4: 1.647643 | AT4: 76.21999 | AU4: 0.39246 | AV4: 1.60022 | AW4: 1.32246 | AX4: 4.80066 | AY4: 0 | AZ4: 0.6742607 | BA4: -2.423059
A5: =COUNTA(C5:Q5)-1 -> 6 | B5: =if(C5="",,AS5) -> 1.647643 | C5: =if(and(D$3>1,E5=PROSES!$D$22),,D5) -> 1MENES-1LBUAN-2 | D5: =if(and(F$3>1,F5=PROSES!$B$10),,F5) -> 1MENES-1LBUAN-2 | E5: =if(F5="",,AS5) -> 1.647643 | F5: =if(G5=H5,,(G5&H5)) -> 1MENES-1LBUAN-2 | G5: =if(Z5=PROSES!$E$29,T5,) | H5: =if(X5=PROSES!$E$29,T5,) -> 1MENES-1LBUAN-2 | I5: =if(J5="",,AS5) | J5: =if(and($K$3>1,R5=PROSES!$C$2),,K5) | K5: =if(and($L$3>1,L5=PROSES!$B$2),,L5) | L5: =if(M5=N5,,(M5&N5)) | M5: =if(Z5=PROSES!$B$3,T5,) | N5: =if(X5=PROSES!$B$3,T5,) | O5: =P5&Q5 -> 1MENES-1LBUAN-2 | P5: =if(Z5=PROSES!$B$1,T5,) | Q5: =if(X5=PROSES!$B$1,T5,) -> 1MENES-1LBUAN-2 | R5: =X5&Z5 -> MENES5PLTU Banten 2 | T5: 1MENES-1LBUAN-2 | U5: region1 | V5: region1 | W5: OHL-150kV-TACSR 2X410mm (2730A) | X5: MENES5 | Y5: II-5 | Z5: PLTU Banten 2 | AA5: I | AD5: 0 | AE5: 1 | AG5: 6.2 | AH5: 1 | AI5: Ground | AJ5: 0 | AM5: 0 | AN5: 0 | AO5: 100 | AP5: 1 | AQ5: 2.73 | AR5: 2.73 | AS5: 1.647643 | AT5: 76.21999 | AU5: 0.39246 | AV5: 1.60022 | AW5: 1.32246 | AX5: 4.80066 | AY5: 0 | AZ5: 0.6742607 | BA5: -2.423059
A6: =COUNTA(C6:Q6)-1 -> 0 | B6: =if(C6="",,AS6) | C6: =if(and(D$3>1,E6=PROSES!$D$22),,D6) | D6: =if(and(F$3>1,F6=PROSES!$B$10),,F6) | E6: =if(F6="",,AS6) | F6: =if(G6=H6,,(G6&H6)) | G6: =if(Z6=PROSES!$E$29,T6,) | H6: =if(X6=PROSES!$E$29,T6,) | I6: =if(J6="",,AS6) | J6: =if(and($K$3>1,R6=PROSES!$C$2),,K6) | K6: =if(and($L$3>1,L6=PROSES!$B$2),,L6) | L6: =if(M6=N6,,(M6&N6)) | M6: =if(Z6=PROSES!$B$3,T6,) | N6: =if(X6=PROSES!$B$3,T6,) | O6: =P6&Q6 | P6: =if(Z6=PROSES!$B$1,T6,) | Q6: =if(X6=PROSES!$B$1,T6,) | R6: =X6&Z6 -> PLTU Banten 2SAKETI5 | T6: 1SAKETI-1LBUAN-1 | U6: region1 | V6: region1 | W6: OHL-150kV-TACSR 2X410mm (2730A) | X6: PLTU Banten 2 | Y6: I | Z6: SAKETI5 | AA6: I-5 | AD6: 0 | AE6: 1 | AG6: 20.299 | AH6: 1 | AI6: Ground | AJ6: 0 | AM6: 0 | AN6: 0 | AO6: 100 | AP6: 1 | AQ6: 2.73 | AR6: 2.73 | AS6: 5.394438 | AT6: 76.21999 | AU6: 1.284927 | AV6: 5.239172 | AW6: 4.329777 | AX6: 15.71751 | AY6: 0 | AZ6: 0.6742607 | BA6: -2.423059
A7: =COUNTA(C7:Q7)-1 -> 0 | B7: =if(C7="",,AS7) | C7: =if(and(D$3>1,E7=PROSES!$D$22),,D7) | D7: =if(and(F$3>1,F7=PROSES!$B$10),,F7) | E7: =if(F7="",,AS7) | F7: =if(G7=H7,,(G7&H7)) | G7: =if(Z7=PROSES!$E$29,T7,) | H7: =if(X7=PROSES!$E$29,T7,) | I7: =if(J7="",,AS7) | J7: =if(and($K$3>1,R7=PROSES!$C$2),,K7) | K7: =if(and($L$3>1,L7=PROSES!$B$2),,L7) | L7: =if(M7=N7,,(M7&N7)) | M7: =if(Z7=PROSES!$B$3,T7,) | N7: =if(X7=PROSES!$B$3,T7,) | O7: =P7&Q7 | P7: =if(Z7=PROSES!$B$1,T7,) | Q7: =if(X7=PROSES!$B$1,T7,) | R7: =X7&Z7 -> SAKETI5PLTU Banten 2 | T7: 1SAKETI-1LBUAN-2 | U7: region1 | V7: region1 | W7: OHL-150kV-TACSR 2X410mm (2730A) | X7: SAKETI5 | Y7: II-5 | Z7: PLTU Banten 2 | AA7: I | AD7: 0 | AE7: 1 | AG7: 20.299 | AH7: 1 | AI7: Ground | AJ7: 0 | AM7: 0 | AN7: 0 | AO7: 100 | AP7: 1 | AQ7: 2.73 | AR7: 2.73 | AS7: 5.394438 | AT7: 76.21999 | AU7: 1.284927 | AV7: 5.239172 | AW7: 4.329777 | AX7: 15.71751 | AY7: 0 | AZ7: 0.6742607 | BA7: -2.423059
A8: =COUNTA(C8:Q8)-1 -> 0 | B8: =if(C8="",,AS8) | C8: =if(and(D$3>1,E8=PROSES!$D$22),,D8) | D8: =if(and(F$3>1,F8=PROSES!$B$22),,F8) | E8: =if(F8="",,AS8) | F8: =if(G8=H8,,(G8&H8)) | G8: =if(Z8=PROSES!$E$29,T8,) | H8: =if(X8=PROSES!$E$29,T8,) | I8: =if(J8="",,AS8) | J8: =if(and($K$3>1,R8=PROSES!$C$2),,K8) | K8: =if(and($L$3>1,L8=PROSES!$B$2),,L8) | L8: =if(M8=N8,,(M8&N8)) | M8: =if(Z8=PROSES!$B$3,T8,) | N8: =if(X8=PROSES!$B$3,T8,) | O8: =P8&Q8 | P8: =if(Z8=PROSES!$B$1,T8,) | Q8: =if(X8=PROSES!$B$1,T8,) | R8: =X8&Z8 -> SPINMILLSPINMILL CONSUMER | T8: 1SPINML-CNSMR | U8: region1 | V8: region1 | W8: CAB-150kV-XLPE-CU-BRUG 1000mm (897 A) | X8: SPINMILL | Y8: 43470 | Z8: SPINMILL CONSUMER | AA8: 43470 | AD8: 0 | AE8: 1 | AG8: 3.7 | AH8: 1 | AI8: Ground | AJ8: 0 | AM8: 0 | AN8: 0 | AO8: 100 | AP8: 1 | AQ8: 0.897 | AR8: 0.897 | AS8: 0.8897078 | AT8: 67.40213 | AU8: 0.34188 | AV8: 0.8214 | AW8: 13.67631 | AX8: 0.30118 | AY8: 0 | AZ8: 4.999609 | BA8: -69.63629
A9: =COUNTA(C9:Q9)-1 -> 0 | B9: =if(C9="",,AS9) | C9: =if(and(D$3>1,E9=PROSES!$D$22),,D9) | D9: =if(and(F$3>1,F9=PROSES!$B$10),,F9) | E9: =if(F9="",,AS9) | F9: =if(G9=H9,,(G9&H9)) | G9: =if(Z9=PROSES!$E$29,T9,) | H9: =if(X9=PROSES!$E$29,T9,) | I9: =if(J9="",,AS9) | J9: =if(and($K$3>1,R9=PROSES!$C$2),,K9) | K9: =if(and($L$3>1,L9=PROSES!$B$2),,L9) | L9: =if(M9=N9,,(M9&N9)) | M9: =if(Z9=PROSES!$B$3,T9,) | N9: =if(X9=PROSES!$B$3,T9,) | O9: =P9&Q9 | P9: =if(Z9=PROSES!$B$1,T9,) | Q9: =if(X9=PROSES!$B$1,T9,) | R9: =X9&Z9 -> KESUGIHAN7ADIPALA7 | T9: ADPLA - KSGHN 1 | U9: 500kV | V9: 500kV | W9: OHL-500kV-ACSR-ZEBRA 4X484.5mm (3240A) | X9: KESUGIHAN7 | Y9: B | Z9: ADIPALA7 | AA9: B | AD9: 0 | AE9: 1 | AG9: 13.83 | AH9: 1 | AI9: Ground | AJ9: 0 | AM9: 0 | AN9: 0 | AO9: 100 | AP9: 1 | AQ9: 3.24 | AR9: 3.24 | AS9: 3.179006 | AT9: 85.0335 | AU9: 0.275217 | AV9: 3.16707 | AW9: 2.349717 | AX9: 9.501209 | AY9: 0 | AZ9: 0.6988767 | BA9: -13.16769
A10: =COUNTA(C10:Q10)-1 -> 0 | B10: =if(C10="",,AS10) | C10: =if(and(D$3>1,E10=PROSES!$D$22),,D10) | D10: =if(and(F$3>1,F10=PROSES!$B$10),,F10) | E10: =if(F10="",,AS10) | F10: =if(G10=H10,,(G10&H10)) | G10: =if(Z10=PROSES!$E$29,T10,) | H10: =if(X10=PROSES!$E$29,T10,) | I10: =if(J10="",,AS10) | J10: =if(and($K$3>1,R10=PROSES!$C$2),,K10) | K10: =if(and($L$3>1,L10=PROSES!$B$2),,L10) | L10: =if(M10=N10,,(M10&N10)) | M10: =if(Z10=PROSES!$B$3,T10,) | N10: =if(X10=PROSES!$B$3,T10,) | O10: =P10&Q10 | P10: =if(Z10=PROSES!$B$1,T10,) | Q10: =if(X10=PROSES!$B$1,T10,) | R10: =X10&Z10 -> KESUGIHAN7ADIPALA7 | T10: ADPLA - KSGHN 2 | U10: 500kV | V10: 500kV | W10: OHL-500kV-ACSR-ZEBRA 4X484.5mm (3240A) | X10: KESUGIHAN7 | Y10: B | Z10: ADIPALA7 | AA10: B | AD10: 0 | AE10: 1 | AG10: 13.83 | AH10: 1 | AI10: Ground | AJ10: 0 | AM10: 0 | AN10: 0 | AO10: 100 | AP10: 1 | AQ10: 3.24 | AR10: 3.24 | AS10: 3.179006 | AT10: 85.0335 | AU10: 0.275217 | AV10: 3.16707 | AW10: 2.349717 | AX10: 9.501209 | AY10: 0 | AZ10: 0.6988767 | BA10: -13.16769
A11: =COUNTA(C11:Q11)-1 -> 0 | B11: =if(C11="",,AS11) | C11: =if(and(D$3>1,E11=PROSES!$D$22),,D11) | D11: =if(and(F$3>1,F11=PROSES!$B$10),,F11) | E11: =if(F11="",,AS11) | F11: =if(G11=H11,,(G11&H11)) | G11: =if(Z11=PROSES!$E$29,T11,) | H11: =if(X11=PROSES!$E$29,T11,) | I11: =if(J11="",,AS11) | J11: =if(and($K$3>1,R11=PROSES!$C$2),,K11) | K11: =if(and($L$3>1,L11=PROSES!$B$2),,L11) | L11: =if(M11=N11,,(M11&N11)) | M11: =if(Z11=PROSES!$B$3,T11,) | N11: =if(X11=PROSES!$B$3,T11,) | O11: =P11&Q11 | P11: =if(Z11=PROSES!$B$1,T11,) | Q11: =if(X11=PROSES!$B$1,T11,) | R11: =X11&Z11 -> ALTA PRIMA5SURABAYA BARAT5 | T11: ALTAP-SBBRT 1 | U11: region4 | V11: region4 | W11: OHL-150kV-ACSR AW 2x340 mm2 (1480A) | X11: ALTA PRIMA5 | Y11: 5-I | Z11: SURABAYA BARAT5 | AA11: 5-I | AD11: 0 | AE11: 1 | AG11: 18.849 | AH11: 1 | AI11: Ground | AJ11: 0 | AM11: 0 | AN11: 0 | AO11: 100 | AP11: 1 | AQ11: 1.48 | AR11: 1.48 | AS11: 3.71445 | AT11: 75.63232 | AU11: 0.9217162 | AV11: 3.598274 | AW11: 3.162862 | AX11: 11.58177 | AY11: 0 | AZ11: 0.7441298 | BA11: -1.31295
A12: =COUNTA(C12:Q12)-1 -> 0 | B12: =if(C12="",,AS12) | C12: =if(and(D$3>1,E12=PROSES!$D$22),,D12) | D12: =if(and(F$3>1,F12=PROSES!$B$10),,F12) | E12: =if(F12="",,AS12) | F12: =if(G12=H12,,(G12&H12)) | G12: =if(Z12=PROSES!$E$29,T12,) | H12: =if(X12=PROSES!$E$29,T12,) | I12: =if(J12="",,AS12) | J12: =if(and($K$3>1,R12=PROSES!$C$2),,K12) | K12: =if(and($L$3>1,L12=PROSES!$B$2),,L12) | L12: =if(M12=N12,,(M12&N12)) | M12: =if(Z12=PROSES!$B$3,T12,) | N12: =if(X12=PROSES!$B$3,T12,) | O12: =P12&Q12 | P12: =if(Z12=PROSES!$B$1,T12,) | Q12: =if(X12=PROSES!$B$1,T12,) | R12: =X12&Z12 -> ALTA PRIMA5SURABAYA BARAT5 | T12: ALTAP-SBBRT 2 | U12: region4 | V12: region4 | W12: OHL-150kV-ACSR AW 2x340 mm2 (1480A) | X12: ALTA PRIMA5 | Y12: 5-II | Z12: SURABAYA BARAT5 | AA12: 5-I | AD12: 0 | AE12: 1 | AG12: 18.849 | AH12: 1 | AI12: Ground | AJ12: 0 | AM12: 0 | AN12: 0 | AO12: 100 | AP12: 1 | AQ12: 1.48 | AR12: 1.48 | AS12: 3.71445 | AT12: 75.63232 | AU12: 0.9217162 | AV12: 3.598274 | AW12: 3.162862 | AX12: 11.58177 | AY12: 0 | AZ12: 0.7441298 | BA12: -1.31295
A13: =COUNTA(C13:Q13)-1 -> 0 | B13: =if(C13="",,AS13) | C13: =if(and(D$3>1,E13=PROSES!$D$22),,D13) | D13: =if(and(F$3>1,F13=PROSES!$B$10),,F13) | E13: =if(F13="",,AS13) | F13: =if(G13=H13,,(G13&H13)) | G13: =if(Z13=PROSES!$E$29,T13,) | H13: =if(X13=PROSES!$E$29,T13,) | I13: =if(J13="",,AS13) | J13: =if(and($K$3>1,R13=PROSES!$C$2),,K13) | K13: =if(and($L$3>1,L13=PROSES!$B$2),,L13) | L13: =if(M13=N13,,(M13&N13)) | M13: =if(Z13=PROSES!$B$3,T13,) | N13: =if(X13=PROSES!$B$3,T13,) | O13: =P13&Q13 | P13: =if(Z13=PROSES!$B$1,T13,) | Q13: =if(X13=PROSES!$B$1,T13,) | R13: =X13&Z13 -> ANCOLKEMAYORAN | T13: ANCOL-KMYRN -1 | U13: region1 | V13: region1 | W13: OHL-150kV-ZEBRA 2X484.5mm (1620A) | X13: ANCOL | Y13: II-5 | Z13: KEMAYORAN | AA13: I-5 | AD13: 0 | AE13: 1 | AG13: 6.2 | AH13: 1 | AI13: Ground | AJ13: 0 | AM13: 0 | AN13: 0 | AO13: 100 | AP13: 1 | AQ13: 1.62 | AR13: 1.62 | AS13: 1.756802 | AT13: 82.15014 | AU13: 0.23994 | AV13: 1.74034 | AW13: 1.16994 | AX13: 5.22102 | AY13: 0 | AZ13: 0.683587 | BA13: -7.109503
A14: =COUNTA(C14:Q14)-1 -> 0 | B14: =if(C14="",,AS14) | C14: =if(and(D$3>1,E14=PROSES!$D$22),,D14) | D14: =if(and(F$3>1,F14=PROSES!$B$10),,F14) | E14: =if(F14="",,AS14) | F14: =if(G14=H14,,(G14&H14)) | G14: =if(Z14=PROSES!$E$29,T14,) | H14: =if(X14=PROSES!$E$29,T14,) | I14: =if(J14="",,AS14) | J14: =if(and($K$3>1,R14=PROSES!$C$2),,K14) | K14: =if(and($L$3>1,L14=PROSES!$B$2),,L14) | L14: =if(M14=N14,,(M14&N14)) | M14: =if(Z14=PROSES!$B$3,T14,) | N14: =if(X14=PROSES!$B$3,T14,) | O14: =P14&Q14 | P14: =if(Z14=PROSES!$B$1,T14,) | Q14: =if(X14=PROSES!$B$1,T14,) | R14: =X14&Z14 -> ANCOLKEMAYORAN | T14: ANCOL-KMYRN -2 | U14: region1 | V14: region1 | W14: OHL-150kV-ZEBRA 2X484.5mm (1620A) | X14: ANCOL | Y14: II-5 | Z14: KEMAYORAN | AA14: II-5 | AD14: 0 | AE14: 1 | AG14: 6.2 | AH14: 1 | AI14: Ground | AJ14: 0 | AM14: 0 | AN14: 0 | AO14: 100 | AP14: 1 | AQ14: 1.62 | AR14: 1.62 | AS14: 1.756802 | AT14: 82.15014 | AU14: 0.23994 | AV14: 1.74034 | AW14: 1.16994 | AX14: 5.22102 | AY14: 0 | AZ14: 0.683587 | BA14: -7.109503
A15: =COUNTA(C15:Q15)-1 -> 0 | B15: =if(C15="",,AS15) | C15: =if(and(D$3>1,E15=PROSES!$D$22),,D15) | D15: =if(and(F$3>1,F15=PROSES!$B$10),,F15) | E15: =if(F15="",,AS15) | F15: =if(G15=H15,,(G15&H15)) | G15: =if(Z15=PROSES!$E$29,T15,) | H15: =if(X15=PROSES!$E$29,T15,) | I15: =if(J15="",,AS15) | J15: =if(and($K$3>1,R15=PROSES!$C$2),,K15) | K15: =if(and($L$3>1,L15=PROSES!$B$2),,L15) | L15: =if(M15=N15,,(M15&N15)) | M15: =if(Z15=PROSES!$B$3,T15,) | N15: =if(X15=PROSES!$B$3,T15,) | O15: =P15&Q15 | P15: =if(Z15=PROSES!$B$1,T15,) | Q15: =if(X15=PROSES!$B$1,T15,) | R15: =X15&Z15 -> ANGKEANCOL | T15: ANGKE-ANCOL -1 | U15: region1 | V15: region1 | W15: OHL-150kV-ACCC-WARSAW 510mm (1714 A) | X15: ANGKE | Y15: II-5 | Z15: ANCOL | AA15: II-5 | AD15: 0 | AE15: 1 | AG15: 4.6 | AH15: 1 | AI15: Ground | AJ15: 0 | AM15: 0 | AN15: 0 | AO15: 100 | AP15: 1 | AQ15: 1.473 | AR15: 1.473 | AS15: 1.232494 | AT15: 70.06567 | AU15: 0.42021 | AV15: 1.158648 | AW15: 1.1086 | AX15: 3.47484 | AY15: 0 | AZ15: 0.6535055 | BA15: 3.381974
A16: =COUNTA(C16:Q16)-1 -> 0 | B16: =if(C16="",,AS16) | C16: =if(and(D$3>1,E16=PROSES!$D$22),,D16) | D16: =if(and(F$3>1,F16=PROSES!$B$10),,F16) | E16: =if(F16="",,AS16) | F16: =if(G16=H16,,(G16&H16)) | G16: =if(Z16=PROSES!$E$29,T16,) | H16: =if(X16=PROSES!$E$29,T16,) | I16: =if(J16="",,AS16) | J16: =if(and($K$3>1,R16=PROSES!$C$2),,K16) | K16: =if(and($L$3>1,L16=PROSES!$B$2),,L16) | L16: =if(M16=N16,,(M16&N16)) | M16: =if(Z16=PROSES!$B$3,T16,) | N16: =if(X16=PROSES!$B$3,T16,) | O16: =P16&Q16 | P16: =if(Z16=PROSES!$B$1,T16,) | Q16: =if(X16=PROSES!$B$1,T16,) | R16: =X16&Z16 -> ANGKEANCOL | T16: ANGKE-ANCOL -2 | U16: region1 | V16: region1 | W16: OHL-150kV-ACCC-WARSAW 510mm (1714 A) | X16: ANGKE | Y16: II-5 | Z16: ANCOL | AA16: II-5 | AD16: 0 | AE16: 1 | AG16: 4.6 | AH16: 1 | AI16: Ground | AJ16: 0 | AM16: 0 | AN16: 0 | AO16: 100 | AP16: 1 | AQ16: 1.473 | AR16: 1.473 | AS16: 1.232494 | AT16: 70.06567 | AU16: 0.42021 | AV16: 1.158648 | AW16: 1.1086 | AX16: 3.47484 | AY16: 0 | AZ16: 0.6535055 | BA16: 3.381974
A17: =COUNTA(C17:Q17)-1 -> 0 | B17: =if(C17="",,AS17) | C17: =if(and(D$3>1,E17=PROSES!$D$22),,D17) | D17: =if(and(F$3>1,F17=PROSES!$B$10),,F17) | E17: =if(F17="",,AS17) | F17: =if(G17=H17,,(G17&H17)) | G17: =if(Z17=PROSES!$E$29,T17,) | H17: =if(X17=PROSES!$E$29,T17,) | I17: =if(J17="",,AS17) | J17: =if(and($K$3>1,R17=PROSES!$C$2),,K17) | K17: =if(and($L$3>1,L17=PROSES!$B$2),,L17) | L17: =if(M17=N17,,(M17&N17)) | M17: =if(Z17=PROSES!$B$3,T17,) | N17: =if(X17=PROSES!$B$3,T17,) | O17: =P17&Q17 | P17: =if(Z17=PROSES!$B$1,T17,) | Q17: =if(X17=PROSES!$B$1,T17,) | R17: =X17&Z17 -> ANGKEKARET | T17: ANGKE-KRLMA-1 | U17: region1 | V17: region1 | W17: OHL-150kV-TACSR 410mm (1200A) (HA222) | X17: ANGKE | Y17: I-5 | Z17: KARET | AA17: I-5 | AD17: 0 | AE17: 1 | AG17: 7.9 | AH17: 1 | AI17: Ground | AJ17: 0 | AM17: 0 | AN17: 0 | AO17: 100 | AP17: 1 | AQ17: 1.2 | AR17: 1.2 | AS17: 1.703774 | AT17: 71.48104 | AU17: 0.54115 | AV17: 1.61555 | AW17: 1.72615 | AX17: 4.84665 | AY17: 0 | AZ17: 0.673318 | BA17: -1.621461
A18: =COUNTA(C18:Q18)-1 -> 0 | B18: =if(C18="",,AS18) | C18: =if(and(D$3>1,E18=PROSES!$D$22),,D18) | D18: =if(and(F$3>1,F18=PROSES!$B$10),,F18) | E18: =if(F18="",,AS18) | F18: =if(G18=H18,,(G18&H18)) | G18: =if(Z18=PROSES!$E$29,T18,) | H18: =if(X18=PROSES!$E$29,T18,) | I18: =if(J18="",,AS18) | J18: =if(and($K$3>1,R18=PROSES!$C$2),,K18) | K18: =if(and($L$3>1,L18=PROSES!$B$2),,L18) | L18: =if(M18=N18,,(M18&N18)) | M18: =if(Z18=PROSES!$B$3,T18,) | N18: =if(X18=PROSES!$B$3,T18,) | O18: =P18&Q18 | P18: =if(Z18=PROSES!$B$1,T18,) | Q18: =if(X18=PROSES!$B$1,T18,) | R18: =X18&Z18 -> ANGKEKARET | T18: ANGKE-KRLMA-2 | U18: region1 | V18: region1 | W18: OHL-150kV-TACSR 410mm (1200A) (HA222) | X18: ANGKE | Y18: I-5 | Z18: KARET | AA18: I-5 | AD18: 0 | AE18: 1 | AG18: 7.9 | AH18: 1 | AI18: Ground | AJ18: 0 | AM18: 0 | AN18: 0 | AO18: 100 | AP18: 1 | AQ18: 1.2 | AR18: 1.2 | AS18: 1.703774 | AT18: 71.48104 | AU18: 0.54115 | AV18: 1.61555 | AW18: 1.72615 | AX18: 4.84665 | AY18: 0 | AZ18: 0.673318 | BA18: -1.621461
A19: =COUNTA(C19:Q19)-1 -> 0 | B19: =if(C19="",,AS19) | C19: =if(and(D$3>1,E19=PROSES!$D$22),,D19) | D19: =if(and(F$3>1,F19=PROSES!$B$10),,F19) | E19: =if(F19="",,AS19) | F19: =if(G19=H19,,(G19&H19)) | G19: =if(Z19=PROSES!$E$29,T19,) | H19: =if(X19=PROSES!$E$29,T19,) | I19: =if(J19="",,AS19) | J19: =if(and($K$3>1,R19=PROSES!$C$2),,K19) | K19: =if(and($L$3>1,L19=PROSES!$B$2),,L19) | L19: =if(M19=N19,,(M19&N19)) | M19: =if(Z19=PROSES!$B$3,T19,) | N19: =if(X19=PROSES!$B$3,T19,) | O19: =P19&Q19 | P19: =if(Z19=PROSES!$B$1,T19,) | Q19: =if(X19=PROSES!$B$1,T19,) | R19: =X19&Z19 -> ANGKEKETAPANG | T19: ANGKE-KTPNG-1 | U19: region1 | V19: region1 | W19: CAB-150kV-CU 240mm (550A) | X19: ANGKE | Y19: II-5 | Z19: KETAPANG | AA19: I-5 | AD19: 0 | AE19: 1 | AG19: 5.5 | AH19: 1 | AI19: Ground | AJ19: 0 | AM19: 0 | AN19: 0 | AO19: 100 | AP19: 1 | AQ19: 0.55 | AR19: 0.55 | AS19: 0.8695046 | AT19: 56.61149 | AU19: 0.4785 | AV19: 0.726 | AW19: 1.3035 | AX19: 2.178 | AY19: 0 | AZ19: 0.6402146 | BA19: 3.784061
A20: =COUNTA(C20:Q20)-1 -> 0 | B20: =if(C20="",,AS20) | C20: =if(and(D$3>1,E20=PROSES!$D$22),,D20) | D20: =if(and(F$3>1,F20=PROSES!$B$10),,F20) | E20: =if(F20="",,AS20) | F20: =if(G20=H20,,(G20&H20)) | G20: =if(Z20=PROSES!$E$29,T20,) | H20: =if(X20=PROSES!$E$29,T20,) | I20: =if(J20="",,AS20) | J20: =if(and($K$3>1,R20=PROSES!$C$2),,K20) | K20: =if(and($L$3>1,L20=PROSES!$B$2),,L20) | L20: =if(M20=N20,,(M20&N20)) | M20: =if(Z20=PROSES!$B$3,T20,) | N20: =if(X20=PROSES!$B$3,T20,) | O20: =P20&Q20 | P20: =if(Z20=PROSES!$B$1,T20,) | Q20: =if(X20=PROSES!$B$1,T20,) | R20: =X20&Z20 -> ANGKEKETAPANG | T20: ANGKE-KTPNG-2 | U20: region1 | V20: region1 | W20: CAB-150kV-CU 240mm (550A) | X20: ANGKE | Y20: II-5 | Z20: KETAPANG | AA20: I-5 | AD20: 0 | AE20: 1 | AG20: 5.5 | AH20: 1 | AI20: Ground | AJ20: 0 | AM20: 0 | AN20: 0 | AO20: 100 | AP20: 1 | AQ20: 0.55 | AR20: 0.55 | AS20: 0.8695046 | AT20: 56.61149 | AU20: 0.4785 | AV20: 0.726 | AW20: 1.3035 | AX20: 2.178 | AY20: 0 | AZ20: 0.6402146 | BA20: 3.784061
... A39: =COUNTA(C39:Q39)-1 -> 0 | B39: =if(C39="",,AS39) | C39: =if(and(D$3>1,E39=PROSES!$D$22),,D39) | D39: =if(and(F$3>1,F39=PROSES!$B$10),,F39) | E39: =if(F39="",,AS39) | F39: =if(G39=H39,,(G39&H39)) | G39: =if(Z39=PROSES!$E$29,T39,) | H39: =if(X39=PROSES!$E$29,T39,) | I39: =if(J39="",,AS39) | J39: =if(and($K$3>1,R39=PROSES!$C$2),,K39) | K39: =if(and($L$3>1,L39=PROSES!$B$2),,L39) | L39: =if(M39=N39,,(M39&N39)) | M39: =if(Z39=PROSES!$B$3,T39,) | N39: =if(X39=PROSES!$B$3,T39,) | O39: =P39&Q39 | P39: =if(Z39=PROSES!$B$1,T39,) | Q39: =if(X39=PROSES!$B$1,T39,) | R39: =X39&Z39 -> ASAHIMAS PWR PLANTASAHIMAS MRS | T39: ASHPP-ASMRS2 | U39: region1 | V39: region1 | W39: CAB-150kV-XLPE-CU 1400mm (1300A) | X39: ASAHIMAS PWR PLANT | Y39: II-5 | Z39: ASAHIMAS MRS | AA39: II-5 | AD39: 1 | AE39: 1 | AG39: 1.2 | AH39: 1 | AI39: Ground | AJ39: 0 | AM39: 0 | AN39: 0 | AO39: 100 | AP39: 1 | AQ39: 1.3 | AR39: 1.3 | AS39: 0.3051929 | AT39: 87.0926 | AU39: 0.01548 | AV39: 0.3048 | AW39: 0.19548 | AX39: 0.9144 | AY39: 0 | AZ39: 0.6942272 | BA39: -13.54318
A40: =COUNTA(C40:Q40)-1 -> 0 | B40: =if(C40="",,AS40) | C40: =if(and(D$3>1,E40=PROSES!$D$22),,D40) | D40: =if(and(F$3>1,F40=PROSES!$B$10),,F40) | E40: =if(F40="",,AS40) | F40: =if(G40=H40,,(G40&H40)) | G40: =if(Z40=PROSES!$E$29,T40,) | H40: =if(X40=PROSES!$E$29,T40,) | I40: =if(J40="",,AS40) | J40: =if(and($K$3>1,R40=PROSES!$C$2),,K40) | K40: =if(and($L$3>1,L40=PROSES!$B$2),,L40) | L40: =if(M40=N40,,(M40&N40)) | M40: =if(Z40=PROSES!$B$3,T40,) | N40: =if(X40=PROSES!$B$3,T40,) | O40: =P40&Q40 | P40: =if(Z40=PROSES!$B$1,T40,) | Q40: =if(X40=PROSES!$B$1,T40,) | R40: =X40&Z40 -> TANJUNG AWAR - AWARBABAT5 | T40: BABAT - T AWAR 1 | U40: region4 | V40: region4 | W40: OHL-150kV-TACSR 2X410/67mm2(2730A) | X40: TANJUNG AWAR - AWAR | Y40: 2 | Z40: BABAT5 | AA40: 5-I | AD40: 0 | AE40: 1 | AG40: 42.37 | AH40: 1 | AI40: Ground | AJ40: 0 | AM40: 0 | AN40: 0 | AO40: 100 | AP40: 1 | AQ40: 2.73 | AR40: 2.73 | AS40: 11.93037 | AT40: 82.244 | AU40: 1.61006 | AV40: 11.82123 | AW40: 7.11816 | AX40: 34.29851 | AY40: 0 | AZ40: 0.6465942 | BA40: -6.013103
A41: =COUNTA(C41:Q41)-1 -> 0 | B41: =if(C41="",,AS41) | C41: =if(and(D$3>1,E41=PROSES!$D$22),,D41) | D41: =if(and(F$3>1,F41=PROSES!$B$10),,F41) | E41: =if(F41="",,AS41) | F41: =if(G41=H41,,(G41&H41)) | G41: =if(Z41=PROSES!$E$29,T41,) | H41: =if(X41=PROSES!$E$29,T41,) | I41: =if(J41="",,AS41) | J41: =if(and($K$3>1,R41=PROSES!$C$2),,K41) | K41: =if(and($L$3>1,L41=PROSES!$B$2),,L41) | L41: =if(M41=N41,,(M41&N41)) | M41: =if(Z41=PROSES!$B$3,T41,) | N41: =if(X41=PROSES!$B$3,T41,) | O41: =P41&Q41 | P41: =if(Z41=PROSES!$B$1,T41,) | Q41: =if(X41=PROSES!$B$1,T41,) | R41: =X41&Z41 -> TANJUNG AWAR - AWARBABAT5 | T41: BABAT - T AWAR 2 | U41: region4 | V41: region4 | W41: OHL-150kV-TACSR 2X410/67mm2(2730A) | X41: TANJUNG AWAR - AWAR | Y41: 1 | Z41: BABAT5 | AA41: 5-II | AD41: 0 | AE41: 1 | AG41: 42.37 | AH41: 1 | AI41: Ground | AJ41: 0 | AM41: 0 | AN41: 0 | AO41: 100 | AP41: 1 | AQ41: 2.73 | AR41: 2.73 | AS41: 11.93037 | AT41: 82.244 | AU41: 1.61006 | AV41: 11.82123 | AW41: 7.11816 | AX41: 34.29851 | AY41: 0 | AZ41: 0.6465942 | BA41: -6.013103
A42: =COUNTA(C42:Q42)-1 -> 0 | B42: =if(C42="",,AS42) | C42: =if(and(D$3>1,E42=PROSES!$D$22),,D42) | D42: =if(and(F$3>1,F42=PROSES!$B$10),,F42) | E42: =if(F42="",,AS42) | F42: =if(G42=H42,,(G42&H42)) | G42: =if(Z42=PROSES!$E$29,T42,) | H42: =if(X42=PROSES!$E$29,T42,) | I42: =if(J42="",,AS42) | J42: =if(and($K$3>1,R42=PROSES!$C$2),,K42) | K42: =if(and($L$3>1,L42=PROSES!$B$2),,L42) | L42: =if(M42=N42,,(M42&N42)) | M42: =if(Z42=PROSES!$B$3,T42,) | N42: =if(X42=PROSES!$B$3,T42,) | O42: =P42&Q42 | P42: =if(Z42=PROSES!$B$1,T42,) | Q42: =if(X42=PROSES!$B$1,T42,) | R42: =X42&Z42 -> BABAT5BOJONEGORO5 | T42: BABAT-BJGRO 1 | U42: region4 | V42: region4 | W42: OHL-150kV-Hawk 240mm (645A) | X42: BABAT5 | Y42: 5-II | Z42: BOJONEGORO5 | AA42: 5-I | AD42: 0 | AE42: 1 | AG42: 35.3 | AH42: 1 | AI42: Ground | AJ42: 0 | AM42: 0 | AN42: 0 | AO42: 100 | AP42: 1 | AQ42: 0.645 | AR42: 0.645 | AS42: 14.82508 | AT42: 70.96105 | AU42: 4.8361 | AV42: 14.0141 | AW42: 10.1311 | AX42: 42.0423 | AY42: 0 | AZ42: 0.6413451 | BA42: 8.340887
A43: =COUNTA(C43:Q43)-1 -> 0 | B43: =if(C43="",,AS43) | C43: =if(and(D$3>1,E43=PROSES!$D$22),,D43) | D43: =if(and(F$3>1,F43=PROSES!$B$10),,F43) | E43: =if(F43="",,AS43) | F43: =if(G43=H43,,(G43&H43)) | G43: =if(Z43=PROSES!$E$29,T43,) | H43: =if(X43=PROSES!$E$29,T43,) | I43: =if(J43="",,AS43) | J43: =if(and($K$3>1,R43=PROSES!$C$2),,K43) | K43: =if(and($L$3>1,L43=PROSES!$B$2),,L43) | L43: =if(M43=N43,,(M43&N43)) | M43: =if(Z43=PROSES!$B$3,T43,) | N43: =if(X43=PROSES!$B$3,T43,) | O43: =P43&Q43 | P43: =if(Z43=PROSES!$B$1,T43,) | Q43: =if(X43=PROSES!$B$1,T43,) | R43: =X43&Z43 -> BABAT5BOJONEGORO5 | T43: BABAT-BJGRO 2 | U43: region4 | V43: region4 | W43: OHL-150kV-Hawk 240mm (645A) | X43: BABAT5 | Y43: 5-II | Z43: BOJONEGORO5 | AA43: 5-I | AD43: 0 | AE43: 1 | AG43: 35.3 | AH43: 1 | AI43: Ground | AJ43: 0 | AM43: 0 | AN43: 0 | AO43: 100 | AP43: 1 | AQ43: 0.645 | AR43: 0.645 | AS43: 14.82508 | AT43: 70.96105 | AU43: 4.8361 | AV43: 14.0141 | AW43: 10.1311 | AX43: 42.0423 | AY43: 0 | AZ43: 0.6413451 | BA43: 8.340887
A44: =COUNTA(C44:Q44)-1 -> 0 | B44: =if(C44="",,AS44) | C44: =if(and(D$3>1,E44=PROSES!$D$22),,D44) | D44: =if(and(F$3>1,F44=PROSES!$B$10),,F44) | E44: =if(F44="",,AS44) | F44: =if(G44=H44,,(G44&H44)) | G44: =if(Z44=PROSES!$E$29,T44,) | H44: =if(X44=PROSES!$E$29,T44,) | I44: =if(J44="",,AS44) | J44: =if(and($K$3>1,R44=PROSES!$C$2),,K44) | K44: =if(and($L$3>1,L44=PROSES!$B$2),,L44) | L44: =if(M44=N44,,(M44&N44)) | M44: =if(Z44=PROSES!$B$3,T44,) | N44: =if(X44=PROSES!$B$3,T44,) | O44: =P44&Q44 | P44: =if(Z44=PROSES!$B$1,T44,) | Q44: =if(X44=PROSES!$B$1,T44,) | R44: =X44&Z44 -> BALARAJASUVARNA SUTERA | T44: BALARAJA-SUVARNA 1 | U44: region1 | V44: region1 | W44: OHL-150kV-ZEBRA 4X428.9 mm (3000A) | X44: BALARAJA | Y44: I-5 | Z44: SUVARNA SUTERA | AA44: 43470 | AD44: 0 | AE44: 1 | AG44: 5.4 | AH44: 1 | AI44: Ground | AJ44: 0 | AM44: 0 | AN44: 0 | AO44: 100 | AP44: 1 | AQ44: 3 | AR44: 3 | AS44: 1.447933 | AT44: 85.75453 | AU44: 0.10719 | AV44: 1.44396 | AW44: 0.9171901 | AX44: 4.33188 | AY44: 0 | AZ44: 0.6904932 | BA44: -11.4222
A45: =COUNTA(C45:Q45)-1 -> 0 | B45: =if(C45="",,AS45) | C45: =if(and(D$3>1,E45=PROSES!$D$22),,D45) | D45: =if(and(F$3>1,F45=PROSES!$B$10),,F45) | E45: =if(F45="",,AS45) | F45: =if(G45=H45,,(G45&H45)) | G45: =if(Z45=PROSES!$E$29,T45,) | H45: =if(X45=PROSES!$E$29,T45,) | I45: =if(J45="",,AS45) | J45: =if(and($K$3>1,R45=PROSES!$C$2),,K45) | K45: =if(and($L$3>1,L45=PROSES!$B$2),,L45) | L45: =if(M45=N45,,(M45&N45)) | M45: =if(Z45=PROSES!$B$3,T45,) | N45: =if(X45=PROSES!$B$3,T45,) | O45: =P45&Q45 | P45: =if(Z45=PROSES!$B$1,T45,) | Q45: =if(X45=PROSES!$B$1,T45,) | R45: =X45&Z45 -> BALARAJASUVARNA SUTERA | T45: BALARAJA-SUVARNA 2 | U45: region1 | V45: region1 | W45: OHL-150kV-ZEBRA 4X428.9 mm (3000A) | X45: BALARAJA | Y45: I-5 | Z45: SUVARNA SUTERA | AA45: 43501 | AD45: 0 | AE45: 1 | AG45: 5.4 | AH45: 1 | AI45: Ground | AJ45: 0 | AM45: 0 | AN45: 0 | AO45: 100 | AP45: 1 | AQ45: 3 | AR45: 3 | AS45: 1.447933 | AT45: 85.75453 | AU45: 0.10719 | AV45: 1.44396 | AW45: 0.9171901 | AX45: 4.33188 | AY45: 0 | AZ45: 0.6904932 | BA45: -11.4222
A46: =COUNTA(C46:Q46)-1 -> 0 | B46: =if(C46="",,AS46) | C46: =if(and(D$3>1,E46=PROSES!$D$22),,D46) | D46: =if(and(F$3>1,F46=PROSES!$B$10),,F46) | E46: =if(F46="",,AS46) | F46: =if(G46=H46,,(G46&H46)) | G46: =if(Z46=PROSES!$E$29,T46,) | H46: =if(X46=PROSES!$E$29,T46,) | I46: =if(J46="",,AS46) | J46: =if(and($K$3>1,R46=PROSES!$C$2),,K46) | K46: =if(and($L$3>1,L46=PROSES!$B$2),,L46) | L46: =if(M46=N46,,(M46&N46)) | M46: =if(Z46=PROSES!$B$3,T46,) | N46: =if(X46=PROSES!$B$3,T46,) | O46: =P46&Q46 | P46: =if(Z46=PROSES!$B$1,T46,) | Q46: =if(X46=PROSES!$B$1,T46,) | R46: =X46&Z46 -> BANGKALAN5SAMPANG5 | T46: BANGKALAN - SAMPANG 1 | U46: region4 | V46: region4 | W46: OHL-150kV-HAWK 1x240(645A) | X46: BANGKALAN5 | Y46: 5-I | Z46: SAMPANG5 | AA46: 5-I | AD46: 0 | AE46: 1 | AG46: 55.369 | AH46: 1 | AI46: Ground | AJ46: 0 | AM46: 0 | AN46: 0 | AO46: 100 | AP46: 1 | AQ46: 0.645 | AR46: 0.645 | AS46: 23.25353 | AT46: 70.96105 | AU46: 7.585553 | AV46: 21.98149 | AW46: 15.8909 | AX46: 65.94448 | AY46: 0 | AZ46: 0.6413451 | BA46: 8.340887
A47: =COUNTA(C47:Q47)-1 -> 0 | B47: =if(C47="",,AS47) | C47: =if(and(D$3>1,E47=PROSES!$D$22),,D47) | D47: =if(and(F$3>1,F47=PROSES!$B$10),,F47) | E47: =if(F47="",,AS47) | F47: =if(G47=H47,,(G47&H47)) | G47: =if(Z47=PROSES!$E$29,T47,) | H47: =if(X47=PROSES!$E$29,T47,) | I47: =if(J47="",,AS47) | J47: =if(and($K$3>1,R47=PROSES!$C$2),,K47) | K47: =if(and($L$3>1,L47=PROSES!$B$2),,L47) | L47: =if(M47=N47,,(M47&N47)) | M47: =if(Z47=PROSES!$B$3,T47,) | N47: =if(X47=PROSES!$B$3,T47,) | O47: =P47&Q47 | P47: =if(Z47=PROSES!$B$1,T47,) | Q47: =if(X47=PROSES!$B$1,T47,) | R47: =X47&Z47 -> BANGKALAN5SAMPANG5 | T47: BANGKALAN - SAMPANG 2 | U47: region4 | V47: region4 | W47: OHL-150kV-HAWK 1x240(645A) | X47: BANGKALAN5 | Y47: 5-II | Z47: SAMPANG5 | AA47: 5-II | AD47: 0 | AE47: 1 | AG47: 55.369 | AH47: 1 | AI47: Ground | AJ47: 0 | AM47: 0 | AN47: 0 | AO47: 100 | AP47: 1 | AQ47: 0.645 | AR47: 0.645 | AS47: 23.25353 | AT47: 70.96105 | AU47: 7.585553 | AV47: 21.98149 | AW47: 15.8909 | AX47: 65.94448 | AY47: 0 | AZ47: 0.6413451 | BA47: 8.340887
A48: =COUNTA(C48:Q48)-1 -> 0 | B48: =if(C48="",,AS48) | C48: =if(and(D$3>1,E48=PROSES!$D$22),,D48) | D48: =if(and(F$3>1,F48=PROSES!$B$10),,F48) | E48: =if(F48="",,AS48) | F48: =if(G48=H48,,(G48&H48)) | G48: =if(Z48=PROSES!$E$29,T48,) | H48: =if(X48=PROSES!$E$29,T48,) | I48: =if(J48="",,AS48) | J48: =if(and($K$3>1,R48=PROSES!$C$2),,K48) | K48: =if(and($L$3>1,L48=PROSES!$B$2),,L48) | L48: =if(M48=N48,,(M48&N48)) | M48: =if(Z48=PROSES!$B$3,T48,) | N48: =if(X48=PROSES!$B$3,T48,) | O48: =P48&Q48 | P48: =if(Z48=PROSES!$B$1,T48,) | Q48: =if(X48=PROSES!$B$1,T48,) | R48: =X48&Z48 -> BANJAR5MAJENANG | T48: BANJAR-MAJENANG1 | U48: 500kV | V48: 500kV | W48: OHL-150kV-HAWK 1x281.1mm (580A) | X48: BANJAR5 | Y48: 5-I | Z48: MAJENANG | AA48: 1 | AD48: 0 | AE48: 1 | AG48: 22.88 | AH48: 1 | AI48: Ground | AJ48: 0 | AM48: 0 | AN48: 0 | AO48: 100 | AP48: 1 | AQ48: 0.58 | AR48: 0.58 | AS48: 9.600349 | AT48: 70.94324 | AU48: 3.13456 | AV48: 9.074208 | AW48: 6.56656 | AX48: 27.22262 | AY48: 0 | AZ48: 0.6412987 | BA48: 8.348166
A49: =COUNTA(C49:Q49)-1 -> 0 | B49: =if(C49="",,AS49) | C49: =if(and(D$3>1,E49=PROSES!$D$22),,D49) | D49: =if(and(F$3>1,F49=PROSES!$B$10),,F49) | E49: =if(F49="",,AS49) | F49: =if(G49=H49,,(G49&H49)) | G49: =if(Z49=PROSES!$E$29,T49,) | H49: =if(X49=PROSES!$E$29,T49,) | I49: =if(J49="",,AS49) | J49: =if(and($K$3>1,R49=PROSES!$C$2),,K49) | K49: =if(and($L$3>1,L49=PROSES!$B$2),,L49) | L49: =if(M49=N49,,(M49&N49)) | M49: =if(Z49=PROSES!$B$3,T49,) | N49: =if(X49=PROSES!$B$3,T49,) | O49: =P49&Q49 | P49: =if(Z49=PROSES!$B$1,T49,) | Q49: =if(X49=PROSES!$B$1,T49,) | R49: =X49&Z49 -> BANJAR5MAJENANG | T49: BANJAR-MAJENANG2 | U49: 500kV | V49: 500kV | W49: OHL-150kV-HAWK 1x281.1mm (580A) | X49: BANJAR5 | Y49: 5-II | Z49: MAJENANG | AA49: 1 | AD49: 0 | AE49: 1 | AG49: 22.88 | AH49: 1 | AI49: Ground | AJ49: 0 | AM49: 0 | AN49: 0 | AO49: 100 | AP49: 1 | AQ49: 0.58 | AR49: 0.58 | AS49: 9.600349 | AT49: 70.94324 | AU49: 3.13456 | AV49: 9.074208 | AW49: 6.56656 | AX49: 27.22262 | AY49: 0 | AZ49: 0.6412987 | BA49: 8.348166
A50: =COUNTA(C50:Q50)-1 -> 0 | B50: =if(C50="",,AS50) | C50: =if(and(D$3>1,E50=PROSES!$D$22),,D50) | D50: =if(and(F$3>1,F50=PROSES!$B$10),,F50) | E50: =if(F50="",,AS50) | F50: =if(G50=H50,,(G50&H50)) | G50: =if(Z50=PROSES!$E$29,T50,) | H50: =if(X50=PROSES!$E$29,T50,) | I50: =if(J50="",,AS50) | J50: =if(and($K$3>1,R50=PROSES!$C$2),,K50) | K50: =if(and($L$3>1,L50=PROSES!$B$2),,L50) | L50: =if(M50=N50,,(M50&N50)) | M50: =if(Z50=PROSES!$B$3,T50,) | N50: =if(X50=PROSES!$B$3,T50,) | O50: =P50&Q50 | P50: =if(Z50=PROSES!$B$1,T50,) | Q50: =if(X50=PROSES!$B$1,T50,) | R50: =X50&Z50 -> BANTULKLATEN | T50: BANTUL-KLATEN1 | U50: region3 | V50: region3 | W50: OHL-150kV-HAWK 1x281.1mm (580A) | X50: BANTUL | Y50: 2 | Z50: KLATEN | AA50: 1 | AD50: 0 | AE50: 1 | AG50: 34.765 | AH50: 1 | AI50: Ground | AJ50: 0 | AM50: 0 | AN50: 0 | AO50: 100 | AP50: 1 | AQ50: 0.58 | AR50: 0.58 | AS50: 14.58724 | AT50: 70.94324 | AU50: 4.762805 | AV50: 13.7878 | AW50: 9.977555 | AX50: 41.3634 | AY50: 0 | AZ50: 0.6412987 | BA50: 8.348166
A51: =COUNTA(C51:Q51)-1 -> 0 | B51: =if(C51="",,AS51) | C51: =if(and(D$3>1,E51=PROSES!$D$22),,D51) | D51: =if(and(F$3>1,F51=PROSES!$B$10),,F51) | E51: =if(F51="",,AS51) | F51: =if(G51=H51,,(G51&H51)) | G51: =if(Z51=PROSES!$E$29,T51,) | H51: =if(X51=PROSES!$E$29,T51,) | I51: =if(J51="",,AS51) | J51: =if(and($K$3>1,R51=PROSES!$C$2),,K51) | K51: =if(and($L$3>1,L51=PROSES!$B$2),,L51) | L51: =if(M51=N51,,(M51&N51)) | M51: =if(Z51=PROSES!$B$3,T51,) | N51: =if(X51=PROSES!$B$3,T51,) | O51: =P51&Q51 | P51: =if(Z51=PROSES!$B$1,T51,) | Q51: =if(X51=PROSES!$B$1,T51,) | R51: =X51&Z51 -> BANTULKLATEN | T51: BANTUL-KLATEN2 | U51: region3 | V51: region3 | W51: OHL-150kV-HAWK 1x281.1mm (580A) | X51: BANTUL | Y51: 1 | Z51: KLATEN | AA51: 1 | AD51: 0 | AE51: 1 | AG51: 34.765 | AH51: 1 | AI51: Ground | AJ51: 0 | AM51: 0 | AN51: 0 | AO51: 100 | AP51: 1 | AQ51: 0.58 | AR51: 0.58 | AS51: 14.58724 | AT51: 70.94324 | AU51: 4.762805 | AV51: 13.7878 | AW51: 9.977555 | AX51: 41.3634 | AY51: 0 | AZ51: 0.6412987 | BA51: 8.348166
A52: =COUNTA(C52:Q52)-1 -> 0 | B52: =if(C52="",,AS52) | C52: =if(and(D$3>1,E52=PROSES!$D$22),,D52) | D52: =if(and(F$3>1,F52=PROSES!$B$10),,F52) | E52: =if(F52="",,AS52) | F52: =if(G52=H52,,(G52&H52)) | G52: =if(Z52=PROSES!$E$29,T52,) | H52: =if(X52=PROSES!$E$29,T52,) | I52: =if(J52="",,AS52) | J52: =if(and($K$3>1,R52=PROSES!$C$2),,K52) | K52: =if(and($L$3>1,L52=PROSES!$B$2),,L52) | L52: =if(M52=N52,,(M52&N52)) | M52: =if(Z52=PROSES!$B$3,T52,) | N52: =if(X52=PROSES!$B$3,T52,) | O52: =P52&Q52 | P52: =if(Z52=PROSES!$B$1,T52,) | Q52: =if(X52=PROSES!$B$1,T52,) | R52: =X52&Z52 -> BANTULSEMANU | T52: BANTUL-SEMANU1 | U52: region3 | V52: region3 | W52: OHL-150kV-HAWK 1x281.1mm (580A) | X52: BANTUL | Y52: 2 | Z52: SEMANU | AA52: 1 | AD52: 0 | AE52: 1 | AG52: 39.043 | AH52: 1 | AI52: Ground | AJ52: 0 | AM52: 0 | AN52: 0 | AO52: 100 | AP52: 1 | AQ52: 0.58 | AR52: 0.58 | AS52: 16.38227 | AT52: 70.94324 | AU52: 5.348891 | AV52: 15.48445 | AW52: 11.20534 | AX52: 46.45336 | AY52: 0 | AZ52: 0.6412987 | BA52: 8.348166
A53: =COUNTA(C53:Q53)-1 -> 0 | B53: =if(C53="",,AS53) | C53: =if(and(D$3>1,E53=PROSES!$D$22),,D53) | D53: =if(and(F$3>1,F53=PROSES!$B$10),,F53) | E53: =if(F53="",,AS53) | F53: =if(G53=H53,,(G53&H53)) | G53: =if(Z53=PROSES!$E$29,T53,) | H53: =if(X53=PROSES!$E$29,T53,) | I53: =if(J53="",,AS53) | J53: =if(and($K$3>1,R53=PROSES!$C$2),,K53) | K53: =if(and($L$3>1,L53=PROSES!$B$2),,L53) | L53: =if(M53=N53,,(M53&N53)) | M53: =if(Z53=PROSES!$B$3,T53,) | N53: =if(X53=PROSES!$B$3,T53,) | O53: =P53&Q53 | P53: =if(Z53=PROSES!$B$1,T53,) | Q53: =if(X53=PROSES!$B$1,T53,) | R53: =X53&Z53 -> BANTULSEMANU | T53: BANTUL-SEMANU2 | U53: region3 | V53: region3 | W53: OHL-150kV-HAWK 1x281.1mm (580A) | X53: BANTUL | Y53: 1 | Z53: SEMANU | AA53: 1 | AD53: 0 | AE53: 1 | AG53: 39.043 | AH53: 1 | AI53: Ground | AJ53: 0 | AM53: 0 | AN53: 0 | AO53: 100 | AP53: 1 | AQ53: 0.58 | AR53: 0.58 | AS53: 16.38227 | AT53: 70.94324 | AU53: 5.348891 | AV53: 15.48445 | AW53: 11.20534 | AX53: 46.45336 | AY53: 0 | AZ53: 0.6412987 | BA53: 8.348166
A54: =COUNTA(C54:Q54)-1 -> 0 | B54: =if(C54="",,AS54) | C54: =if(and(D$3>1,E54=PROSES!$D$22),,D54) | D54: =if(and(F$3>1,F54=PROSES!$B$10),,F54) | E54: =if(F54="",,AS54) | F54: =if(G54=H54,,(G54&H54)) | G54: =if(Z54=PROSES!$E$29,T54,) | H54: =if(X54=PROSES!$E$29,T54,) | I54: =if(J54="",,AS54) | J54: =if(and($K$3>1,R54=PROSES!$C$2),,K54) | K54: =if(and($L$3>1,L54=PROSES!$B$2),,L54) | L54: =if(M54=N54,,(M54&N54)) | M54: =if(Z54=PROSES!$B$3,T54,) | N54: =if(X54=PROSES!$B$3,T54,) | O54: =P54&Q54 | P54: =if(Z54=PROSES!$B$1,T54,) | Q54: =if(X54=PROSES!$B$1,T54,) | R54: =X54&Z54 -> BANTULWATES | T54: BANTUL-WATES | U54: region3 | V54: region3 | W54: OHL-150kV-HAWK 1x281.1mm (580A) | X54: BANTUL | Y54: 2 | Z54: WATES | AA54: 5-I | AD54: 0 | AE54: 1 | AG54: 31.644 | AH54: 1 | AI54: Ground | AJ54: 0 | AM54: 0 | AN54: 0 | AO54: 100 | AP54: 1 | AQ54: 0.58 | AR54: 0.58 | AS54: 13.27769 | AT54: 70.94324 | AU54: 4.335227 | AV54: 12.55001 | AW54: 9.081828 | AX54: 37.65003 | AY54: 0 | AZ54: 0.6412987 | BA54: 8.348166
A55: =COUNTA(C55:Q55)-1 -> 0 | B55: =if(C55="",,AS55) | C55: =if(and(D$3>1,E55=PROSES!$D$22),,D55) | D55: =if(and(F$3>1,F55=PROSES!$B$10),,F55) | E55: =if(F55="",,AS55) | F55: =if(G55=H55,,(G55&H55)) | G55: =if(Z55=PROSES!$E$29,T55,) | H55: =if(X55=PROSES!$E$29,T55,) | I55: =if(J55="",,AS55) | J55: =if(and($K$3>1,R55=PROSES!$C$2),,K55) | K55: =if(and($L$3>1,L55=PROSES!$B$2),,L55) | L55: =if(M55=N55,,(M55&N55)) | M55: =if(Z55=PROSES!$B$3,T55,) | N55: =if(X55=PROSES!$B$3,T55,) | O55: =P55&Q55 | P55: =if(Z55=PROSES!$B$1,T55,) | Q55: =if(X55=PROSES!$B$1,T55,) | R55: =X55&Z55 -> BANYUDONOJAJAR | T55: BANYUDONO-JAJAR | U55: region3 | V55: region3 | W55: OHL-150kV-HAWK 1x281.1mm (580A) | X55: BANYUDONO | Y55: - 3-I | Z55: JAJAR | AA55: 1 | AD55: 0 | AE55: 1 | AG55: 8.65 | AH55: 1 | AI55: Ground | AJ55: 0 | AM55: 0 | AN55: 0 | AO55: 100 | AP55: 1 | AQ55: 0.58 | AR55: 0.58 | AS55: 3.629503 | AT55: 70.94324 | AU55: 1.18505 | AV55: 3.43059 | AW55: 2.48255 | AX55: 10.29177 | AY55: 0 | AZ55: 0.6412987 | BA55: 8.348166
A56: =COUNTA(C56:Q56)-1 -> 0 | B56: =if(C56="",,AS56) | C56: =if(and(D$3>1,E56=PROSES!$D$22),,D56) | D56: =if(and(F$3>1,F56=PROSES!$B$10),,F56) | E56: =if(F56="",,AS56) | F56: =if(G56=H56,,(G56&H56)) | G56: =if(Z56=PROSES!$E$29,T56,) | H56: =if(X56=PROSES!$E$29,T56,) | I56: =if(J56="",,AS56) | J56: =if(and($K$3>1,R56=PROSES!$C$2),,K56) | K56: =if(and($L$3>1,L56=PROSES!$B$2),,L56) | L56: =if(M56=N56,,(M56&N56)) | M56: =if(Z56=PROSES!$B$3,T56,) | N56: =if(X56=PROSES!$B$3,T56,) | O56: =P56&Q56 | P56: =if(Z56=PROSES!$B$1,T56,) | Q56: =if(X56=PROSES!$B$1,T56,) | R56: =X56&Z56 -> PEKALONGANBATANG | T56: BATANG-PEKALONGAN 1 | U56: region3 | V56: region3 | W56: OHL-150kV-HAWK 1x281.1mm (580A) | X56: PEKALONGAN | Y56: 1 | Z56: BATANG | AA56: 2 | AD56: 0 | AE56: 1 | AG56: 13.163 | AH56: 1 | AI56: Ground | AJ56: 0 | AM56: 0 | AN56: 0 | AO56: 100 | AP56: 1 | AQ56: 0.58 | AR56: 0.58 | AS56: 5.523139 | AT56: 70.94324 | AU56: 1.803331 | AV56: 5.220446 | AW56: 3.777781 | AX56: 15.66134 | AY56: 0 | AZ56: 0.6412987 | BA56: 8.348166
A57: =COUNTA(C57:Q57)-1 -> 0 | B57: =if(C57="",,AS57) | C57: =if(and(D$3>1,E57=PROSES!$D$22),,D57) | D57: =if(and(F$3>1,F57=PROSES!$B$10),,F57) | E57: =if(F57="",,AS57) | F57: =if(G57=H57,,(G57&H57)) | G57: =if(Z57=PROSES!$E$29,T57,) | H57: =if(X57=PROSES!$E$29,T57,) | I57: =if(J57="",,AS57) | J57: =if(and($K$3>1,R57=PROSES!$C$2),,K57) | K57: =if(and($L$3>1,L57=PROSES!$B$2),,L57) | L57: =if(M57=N57,,(M57&N57)) | M57: =if(Z57=PROSES!$B$3,T57,) | N57: =if(X57=PROSES!$B$3,T57,) | O57: =P57&Q57 | P57: =if(Z57=PROSES!$B$1,T57,) | Q57: =if(X57=PROSES!$B$1,T57,) | R57: =X57&Z57 -> PEKALONGANBATANG | T57: BATANG-PEKALONGAN 2 | U57: region3 | V57: region3 | W57: OHL-150kV-HAWK 1x281.1mm (580A) | X57: PEKALONGAN | Y57: 2 | Z57: BATANG | AA57: 1 | AD57: 0 | AE57: 1 | AG57: 13.163 | AH57: 1 | AI57: Ground | AJ57: 0 | AM57: 0 | AN57: 0 | AO57: 100 | AP57: 1 | AQ57: 0.58 | AR57: 0.58 | AS57: 5.523139 | AT57: 70.94324 | AU57: 1.803331 | AV57: 5.220446 | AW57: 3.777781 | AX57: 15.66134 | AY57: 0 | AZ57: 0.6412987 | BA57: 8.348166
A58: =COUNTA(C58:Q58)-1 -> 0 | B58: =if(C58="",,AS58) | C58: =if(and(D$3>1,E58=PROSES!$D$22),,D58) | D58: =if(and(F$3>1,F58=PROSES!$B$10),,F58) | E58: =if(F58="",,AS58) | F58: =if(G58=H58,,(G58&H58)) | G58: =if(Z58=PROSES!$E$29,T58,) | H58: =if(X58=PROSES!$E$29,T58,) | I58: =if(J58="",,AS58) | J58: =if(and($K$3>1,R58=PROSES!$C$2),,K58) | K58: =if(and($L$3>1,L58=PROSES!$B$2),,L58) | L58: =if(M58=N58,,(M58&N58)) | M58: =if(Z58=PROSES!$B$3,T58,) | N58: =if(X58=PROSES!$B$3,T58,) | O58: =P58&Q58 | P58: =if(Z58=PROSES!$B$1,T58,) | Q58: =if(X58=PROSES!$B$1,T58,) | R58: =X58&Z58 -> BAWENKLATEN | T58: BAWEN-KLATEN1 | U58: region3 | V58: region3 | W58: OHL-150kV-ZEBRA 2X484.5mm (1620A) | X58: BAWEN | Y58: 1 | Z58: KLATEN | AA58: 1 | AD58: 0 | AE58: 1 | AG58: 64.757 | AH58: 1 | AI58: Ground | AJ58: 0 | AM58: 0 | AN58: 0 | AO58: 100 | AP58: 1 | AQ58: 1.62 | AR58: 1.62 | AS58: 18.34924 | AT58: 82.15014 | AU58: 2.506096 | AV58: 18.17729 | AW58: 12.21965 | AX58: 54.53188 | AY58: 0 | AZ58: 0.683587 | BA58: -7.109503
...

Sheet Sheet26
A1: OHL-500kV-ACSR-ZEBRA 4X484.5mm (3240A)
A2: OHL-500kV-ACSR-ZEBRA 4X484.5mm (3240A) | E2: {=UNIQUE(A:A)} -> OHL-500kV-ACSR-ZEBRA 4X484.5mm (3240A)
A3: OHL-500kV-ACSR-DOVE 4X327.9mm (1980A) | E3: OHL-500kV-ACSR-DOVE 4X327.9mm (1980A)
A4: OHL-500kV-ACSR-DOVE 4X327.9mm (1980A) | E4: OHL-500kV-ACSR-DOVE 4X282/46 mm (2808A)
A5: OHL-500kV-ACSR-DOVE 4X327.9mm (1980A) | E5: OHL-500kV-ACCC-DOVE 4X282mm (4320A)
A6: OHL-500kV-ACSR-DOVE 4X282/46 mm (2808A) | E6: OHL-500kV-ACSR ZEBRA 4x400 mm (3240 A)
A7: OHL-500kV-ACCC-DOVE 4X282mm (4320A) | E7: OHL-500kV-ACSR-GANNET 4X392.8mm (2400A)
A8: OHL-500kV-ACSR-DOVE 4X282/46 mm (2808A) | E8: OHL-500kV-ACSR-DOVE221 4X327.9mm (2400A)
A9: OHL-500kV-ACCC-DOVE 4X282mm (4320A) | E9: OHL-500kV-ACSR-DOVE 4X282/46 mm (2876A)
A10: OHL-500kV-ACSR ZEBRA 4x400 mm (3240 A) | E10: OHL-500kV-ACSR-ZEBRA 4X429/55mm
A11: OHL-500kV-ACSR ZEBRA 4x400 mm (3240 A)
A12: OHL-500kV-ACSR-DOVE 4X327.9mm (1980A)
A13: OHL-500kV-ACSR-DOVE 4X327.9mm (1980A)
A14: OHL-500kV-ACSR-DOVE 4X327.9mm (1980A)
A15: OHL-500kV-ACSR-DOVE 4X327.9mm (1980A)
A16: OHL-500kV-ACSR-GANNET 4X392.8mm (2400A)
A17: OHL-500kV-ACSR-GANNET 4X392.8mm (2400A)
A18: OHL-500kV-ACSR-GANNET 4X392.8mm (2400A)
A19: OHL-500kV-ACSR-ZEBRA 4X484.5mm (3240A)
A20: OHL-500kV-ACSR-ZEBRA 4X484.5mm (3240A)
A21: OHL-500kV-ACSR-DOVE 4X327.9mm (1980A)
A22: OHL-500kV-ACSR-DOVE 4X327.9mm (1980A)
... A116: OHL-500kV-ACSR-DOVE 4X327.9mm (1980A)

Sheet CALCULATION
A1: PERHITUNGAN SETTING DISTANCE
B4: INPUT PARAMETER
C6: KONFIGURASI SALURAN
E8: L1 | J8: L3 | N8: L4 | R8: GI-A | T8: : | U8: =PROSES!E26 -> MENES5
R9: GI-B | T9: : | U9: =PROSES!E27 -> RANGKASBITUNG5
B10: GI-A | L10: GI-D | O10: GI-E | R10: GI-C | T10: : | U10: =PROSES!E28 -> SAKETI5
B11: =U8 -> MENES5 | L11: =U11 -> MENES5 | O11: =U12 -> ASAHIMAS 2 | R11: GI-D | T11: : | U11: =PROSES!E29 -> MENES5
R12: GI-E | T12: : | U12: =PROSES!E30 -> ASAHIMAS 2
I14: L2 | R14: Ratio CT | X14: : | Y14: ='Cek Distance'!C7 -> 1822 | AC14: / | AD14: ='Cek Distance'!E8 -> 1
R15: Ratio PT | X15: : | Y15: ='Cek Distance'!C9 -> 150000 | AC15: / | AD15: ='Cek Distance'!E9 -> 100
G16: GI-B | J16: GI-C | R16: 3phase fault di GI-A | X16: : | Y16: =PROSES!B4*1000 -> 23130 | AE16: A
F17: =U9 -> RANGKASBITUNG5 | K17: =U10 -> SAKETI5 | R17: 1phase fault di GI-A | X17: : | Y17: =PROSES!B5*1000 -> 22120 | AE17: A
R18: Impedansi Trafo di GI-B | X18: : | Y18: 12.5 | AB18: %
R19: Daya Trafo di GI-B | X19: : | Y19: 60 | AB19: MVA
R20: Ratio Trafo di GI-B | X20: : | Y20: ='Cek Distance'!C9/1000 -> 150 | AA20: / | AB20: =IF(Y20=150,20,IF(Y20=500,150,IF(Y20=70,20))) -> 20 | AD20: kV
C23: Parameter L1 | X23: Parameter L3
C24: Nama Saluran | G24: : | H24: =PROSES!B20 -> RKBTG-KOPO 1 | X24: Nama Saluran | AB24: : | AC24: =PROSES!B22 -> ASAHI2-MNES5-2
D25: Jenis Kawat A | H25: : | I25: =PROSES!K20 -> OHL-150kV-ZEBRA 2X484.5mm (1620A) | Y25: Jenis Kawat A | AC25: : | AD25: =PROSES!K22 -> OHL-150kV-TACSR 2X410mm (2730A)
D26: R11A = | F26: =PROSES!L20 -> 0.0387 | J26: ohm/km | P26: L11A= | R26: =PROSES!I20 -> 15.392 | U26: km | Y26: R31A = | AA26: =PROSES!L22 -> 0.063299982 | AE26: ohm/km | AK26: L31A= | AM26: =PROSES!I22 -> 27.515 | AP26: km
D27: X11A = | F27: =PROSES!M20 -> 0.28069997 | J27: ohm/km | P27: In A= | R27: =#REF! -> #REF! | U27: A | Y27: X31A = | AA27: =PROSES!M22 -> 0.25810002 | AE27: ohm/km
D29: Jenis Kawat B | H29: : | Y29: Jenis Kawat B | AC29: :
D30: R11B = | J30: ohm/km | P30: L11B= | U30: km | Y30: R31B = | AE30: ohm/km | AK30: L31B= | AP30: km
D31: X11B = | J31: ohm/km | P31: In B= | U31: A | Y31: X31B = | AE31: ohm/km
D33: Jenis Kawat C | H33: : | Y33: Jenis Kawat C | AC33: :
D34: R11C = | J34: ohm/km | P34: L11C= | U34: km | Y34: R31C = | AE34: ohm/km | AK34: L31C= | AP34: km
D35: X11C = | J35: ohm/km | P35: In C= | U35: A | Y35: X31C = | AE35: ohm/km
C37: Parameter L2 | X37: Parameter L4
C38: Nama Saluran | G38: : | H38: =PROSES!B21 -> SAKETI-RKBTG 1 | X38: Nama Saluran | AB38: : | AC38: =PROSES!B23 -> ASAHI2-MNES5-1
D39: Jenis Kawat A | H39: : | I39: =PROSES!K21 -> OHL-150kV-TACSR 2X410mm (2730A) | Y39: Jenis Kawat A | AC39: : | AD39: =PROSES!K23 -> OHL-150kV-TACSR 2X410mm (2730A)
D40: R21A = | F40: =PROSES!L21 -> 0.063300003 | J40: ohm/km | P40: L21A= | R40: =PROSES!I21 -> 33.803 | U40: km | Y40: R41A = | AA40: =PROSES!L23 -> 0.0633 | AE40: ohm/km | AK40: L41A= | AM40: =PROSES!I23 -> 1.35 | AP40: km
D41: X21A = | F41: =PROSES!M21 -> 0.25810002 | J41: ohm/km | Y41: X41A = | AA41: =PROSES!M23 -> 0.2581 | AE41: ohm/km
D43: Jenis Kawat B | H43: : | Y43: Jenis Kawat B | AC43: :
D44: R21B = | J44: ohm/km | P44: L21B= | U44: km | Y44: R41B = | AE44: ohm/km | AK44: L41B= | AP44: km
D45: X21B = | J45: ohm/km | Y45: X41B = | AE45: ohm/km
D47: Jenis Kawat C | H47: : | Y47: Jenis Kawat C | AC47: :
D48: R21C = | J48: ohm/km | P48: L21C= | U48: km | Y48: R41C = | AE48: ohm/km | AK48: L41C= | AP48: km
D49: X21C = | J49: ohm/km | Y49: X41C = | AE49: ohm/km
B53: CALCULATION PROCESS
C55: PARAMETER L1
C56: RL10A | E56: = | F56: =(PROSES!N20)*R26 -> 2.90447 | J56: Ohm | M56: XL10A | O56: = | P56: =PROSES!O20*R26 -> 12.9616 | T56: Ohm
...

Sheet IHS
E1: Arus Hubung Singkat GI/GITET Sistem Jawa Bali Semester 1 Tahun 2021
R2: Arus Hubung Singkat KIT Aktif BP ROB Feb 2020
E3: No. | F3: Bus | G3: GI/GITET | H3: APB | I3: TEG | J3: Impedansi Urutan Positif | L3: Impedansi Urutan Negatif | N3: Impedansi Urutan Nol | P3: Arus Hubung Singkat | V3: Z base | W3: Impedansi Urutan Positif | Y3: Impedansi Urutan Negatif | AA3: Impedansi Urutan Nol | AC3: Z1 | AD3: Z2 | AE3: Z0 | AF3: Busbar (asumsi) | AG3: SIR
I4: kV | J4: R1(pu) | K4: X1(pu) | L4: R2(pu) | M4: X2(pu) | N4: R0(pu) | O4: X0(pu) | P4: 1ph(kA) | Q4: 3ph(kA) | R4: 1ph(kA) | S4: 3ph(kA) | W4: R1(Ohm) | X4: X1(Ohm) | Y4: R2(Ohm) | Z4: X2(Ohm) | AA4: R0(Ohm) | AB4: X0(Ohm) | AC4: (ohm) | AD4: (ohm) | AE4: (ohm) | AF4: Z=0.5 Ohm
A6: I-5ABADI GUNA PAPAN | B6: I-5 | C6: ABADI GUNA PAPAN | D6: region1 | E6: 1 | F6: B-7 | G6: BEKASI7 | H6: UP2B DKI Jakarta & Banten | I6: 500 | J6: 0.0003 | K6: 0.00378 | L6: 0.0003 | M6: 0.0038 | N6: 0.0004 | O6: 0.00348 | P6: 34.2 | Q6: 33.5 | R6: 30.55 | S6: 28.52
A7: II-5ABADI GUNA PAPAN | B7: II-5 | C7: ABADI GUNA PAPAN | D7: region1 | E7: 2 | F7: A-7 | G7: BEKASI7 | H7: UP2B DKI Jakarta & Banten | I7: 500 | J7: 0.0003 | K7: 0.0038 | L7: 0 | M7: 0 | N7: 0.0004 | O7: 0.00348 | P7: 34.2 | Q7: 33.5 | R7: 30.55 | S7: 28.52
A8: I-5ALAM SUTRA | B8: I-5 | C8: ALAM SUTRA | D8: region1 | E8: 3 | F8: B-7 | G8: CAWANG7 | H8: UP2B DKI Jakarta & Banten | I8: 500 | J8: 0.0003 | K8: 0.0042 | L8: 0 | M8: 0 | N8: 0.00029 | O8: 0.00346 | P8: 32.11 | Q8: 30.47 | R8: 28.51 | S8: 25.86
A9: II-5ALAM SUTRA | B9: II-5 | C9: ALAM SUTRA | D9: region1 | E9: 4 | F9: A-7 | G9: CAWANG7 | H9: UP2B DKI Jakarta & Banten | I9: 500 | J9: 0.0003 | K9: 0.0042 | L9: 0 | M9: 0 | N9: 0.00029 | O9: 0.00346 | P9: 32.11 | Q9: 30.47 | R9: 28.51 | S9: 25.86
A10: I-5ALINDO | B10: I-5 | C10: ALINDO | D10: region1 | E10: 5 | F10: B-7 | G10: CIBINONG7 | H10: UP2B DKI Jakarta & Banten | I10: 500 | J10: 0.0002 | K10: 0.0025 | L10: 0 | M10: 0 | N10: 0.0002 | O10: 0.00171 | P10: 56.5 | Q10: 50.96 | R10: 49.49 | S10: 42.81
A11: I-5ANCOL | B11: I-5 | C11: ANCOL | D11: region1 | E11: 6 | F11: A-7 | G11: CIBINONG7 | H11: UP2B DKI Jakarta & Banten | I11: 500 | J11: 0.0002 | K11: 0.0025 | L11: 0 | M11: 0 | N11: 0.0002 | O11: 0.00171 | P11: 56.5 | Q11: 50.96 | R11: 49.49 | S11: 42.81
A12: II-5ANCOL | B12: II-5 | C12: ANCOL | D12: region1 | E12: 7 | F12: B-7 | G12: CILEGON BARU7 | H12: UP2B DKI Jakarta & Banten | I12: 500 | J12: 0.0002 | K12: 0.003 | L12: 0 | M12: 0 | N12: 0.00033 | O12: 0.00269 | P12: 43.38 | Q12: 42.69 | R12: 40.25 | S12: 38.45
A13: I-5ANGKE | B13: I-5 | C13: ANGKE | D13: region1 | E13: 8 | F13: A-7 | G13: CILEGON BARU7 | H13: UP2B DKI Jakarta & Banten | I13: 500 | J13: 0.0002 | K13: 0.003 | L13: 0 | M13: 0 | N13: 0.00033 | O13: 0.00269 | P13: 43.38 | Q13: 42.69 | R13: 40.25 | S13: 38.45
A14: II-5ANGKE | B14: II-5 | C14: ANGKE | D14: region1 | E14: 9 | F14: B | G14: DEPOK7 | H14: UP2B DKI Jakarta & Banten | I14: 500 | J14: 0.0002 | K14: 0.0026 | L14: 0 | M14: 0 | N14: 0.0002 | O14: 0.00176 | P14: 53.55 | Q14: 47.87 | R14: 47.85 | S14: 41.32
A15: I-5ANTASARI | B15: I-5 | C15: ANTASARI | D15: region1 | E15: 10 | F15: A | G15: DEPOK7 | H15: UP2B DKI Jakarta & Banten | I15: 500 | J15: 0.0002 | K15: 0.0026 | L15: 0 | M15: 0 | N15: 0.0002 | O15: 0.00176 | P15: 53.55 | Q15: 47.87 | R15: 47.85 | S15: 41.32
A16: II-5ANTASARI | B16: II-5 | C16: ANTASARI | D16: region1 | E16: 11 | F16: B-7 | G16: DURIKOSAMBI7 | H16: UP2B DKI Jakarta & Banten | I16: 500 | J16: 0.0003 | K16: 0.0041 | L16: 0 | M16: 0 | N16: 0.00037 | O16: 0.00384 | P16: 31.55 | Q16: 30.92 | R16: 29.5 | S16: 28.06
A17: B1.0ASAHIMAS | B17: B1.0 | C17: ASAHIMAS | D17: region1 | E17: 12 | F17: A-7 | G17: DURIKOSAMBI7 | H17: UP2B DKI Jakarta & Banten | I17: 500 | J17: 0.0003 | K17: 0.0041 | L17: 0 | M17: 0 | N17: 0.00037 | O17: 0.00384 | P17: 31.55 | Q17: 30.92 | R17: 29.5 | S17: 28.06
... A83: II-5CIKANDE | B83: II-5 | C83: CIKANDE | D83: region1 | E83: 78 | F83: I-5 | G83: ABADI GUNA PAPAN | H83: UP2B DKI Jakarta & Banten | I83: 150 | J83: 0.0026 | K83: 0.0186 | L83: 0 | M83: 0.02 | N83: 0.00569 | O83: 0.0203 | P83: 21.6 | Q83: 22.48 | R83: 21.13 | S83: 21.73
A84: I-5CIKUPA | B84: I-5 | C84: CIKUPA | D84: region1 | E84: 79 | F84: 44232 | G84: ALAM SUTRA | H84: UP2B DKI Jakarta & Banten | I84: 150 | J84: 0.0009 | K84: 0.0129 | L84: 0 | M84: 0.01 | N84: 0.00318 | O84: 0.01473 | P84: 30.94 | Q84: 32.68 | R84: 30.54 | S84: 32.03
A85: II-5CIKUPA | B85: II-5 | C85: CIKUPA | D85: region1 | E85: 80 | F85: 44201 | G85: ALAM SUTRA | H85: UP2B DKI Jakarta & Banten | I85: 150 | J85: 0.0009 | K85: 0.0129 | L85: 0 | M85: 0.01 | N85: 0.00318 | O85: 0.01473 | P85: 30.94 | Q85: 32.68 | R85: 30.54 | S85: 32.03
A86: I-5CILEDUG | B86: I-5 | C86: CILEDUG | D86: region1 | E86: 81 | F86: I-5 | G86: ALINDO | H86: UP2B DKI Jakarta & Banten | I86: 150 | J86: 0.0013 | K86: 0.0127 | L86: 0 | M86: 0.01 | N86: 0.0023 | O86: 0.01263 | P86: 32.65 | Q86: 32.96 | R86: 31.49 | S86: 31.23
A87: II-5CILEDUG | B87: II-5 | C87: CILEDUG | D87: region1 | E87: 82 | F87: II-5 | G87: ANCOL | H87: UP2B DKI Jakarta & Banten | I87: 150 | J87: 0.0005 | K87: 0.0072 | L87: 0 | M87: 0.01 | N87: 0.00173 | O87: 0.0088 | P87: 52.88 | Q87: 58.37 | R87: 49.64 | S87: 52.8
A88: A-7CILEGON BARU7 | B88: A-7 | C88: CILEGON BARU7 | D88: region1 | E88: 83 | F88: I-5 | G88: ANCOL | H88: UP2B DKI Jakarta & Banten | I88: 150 | J88: 0.0005 | K88: 0.0072 | L88: 0 | M88: 0.01 | N88: 0.00173 | O88: 0.0088 | P88: 52.88 | Q88: 58.37 | R88: 49.64 | S88: 52.8
A89: B-7CILEGON BARU7 | B89: B-7 | C89: CILEGON BARU7 | D89: region1 | E89: 84 | F89: II-5 | G89: ANGKE | H89: UP2B DKI Jakarta & Banten | I89: 150 | J89: 0.0014 | K89: 0.0097 | L89: 0 | M89: 0.01 | N89: 0.00394 | O89: 0.01606 | P89: 34.53 | Q89: 43.02 | R89: 32.97 | S89: 39.59
A90: I-5CILEGONBARU | B90: I-5 | C90: CILEGONBARU | D90: region1 | E90: 85 | F90: I-5 | G90: ANGKE | H90: UP2B DKI Jakarta & Banten | I90: 150 | J90: 0.0006 | K90: 0.0102 | L90: 0 | M90: 0.01 | N90: 0.00166 | O90: 0.00887 | P90: 44.24 | Q90: 41.26 | R90: 38.3 | S90: 33.65
A91: II-5CILEGONBARU | B91: II-5 | C91: CILEGONBARU | D91: region1 | E91: 86 | F91: II-5 | G91: ANTASARI | H91: UP2B DKI Jakarta & Banten | I91: 150 | J91: 0.0012 | K91: 0.0155 | L91: 0 | M91: 0.02 | N91: 0.00252 | O91: 0.01102 | P91: 29.87 | Q91: 27.17 | R91: 28.97 | S91: 26.07
A92: I-5CILEGONLAMA | B92: I-5 | C92: CILEGONLAMA | D92: region1 | E92: 87 | F92: I-5 | G92: ANTASARI | H92: UP2B DKI Jakarta & Banten | I92: 150 | J92: 0.0012 | K92: 0.0155 | L92: 0 | M92: 0.02 | N92: 0.00252 | O92: 0.01102 | P92: 29.87 | Q92: 27.17 | R92: 28.97 | S92: 26.07
A93: II-5CILEGONLAMA | B93: II-5 | C93: CILEGONLAMA | D93: region1 | E93: 88 | F93: I-5 | G93: ASAHIMAS | H93: UP2B DKI Jakarta & Banten | I93: 150 | J93: 0.0014 | K93: 0.0145 | L93: 0 | M93: 0.01 | N93: 0.00516 | O93: 0.02498 | P93: 23.05 | Q93: 28.94 | R93: 22.62 | S93: 27.94
A94: I-4CILEUNGSI | B94: I-4 | C94: CILEUNGSI | D94: region1 | E94: 89 | F94: II-5 | G94: ASAHIMAS 2 | H94: UP2B DKI Jakarta & Banten | I94: 150 | J94: 0.0024 | K94: 0.0184 | L94: 0 | M94: 0.02 | N94: 0.00778 | O94: 0.03393 | P94: 17.52 | Q94: 22.71 | R94: 17.34 | S94: 22.24
A95: II-4CILEUNGSI | B95: II-4 | C95: CILEUNGSI | D95: region1 | E95: 90 | F95: I-5 | G95: ASAHIMAS 2 | H95: UP2B DKI Jakarta & Banten | I95: 150 | J95: 0.0024 | K95: 0.0184 | L95: 0 | M95: 0.02 | N95: 0.00778 | O95: 0.03393 | P95: 17.52 | Q95: 22.71 | R95: 17.34 | S95: 22.24
A96: I-5CIMANGGIS | B96: I-5 | C96: CIMANGGIS | D96: region1 | E96: 91 | F96: II-5 | G96: ASAHIMAS MRS | H96: UP2B DKI Jakarta & Banten | I96: 150 | J96: 0.0014 | K96: 0.0146 | L96: 0 | M96: 0.01 | N96: 0.00524 | O96: 0.02533 | P96: 22.81 | Q96: 28.71 | R96: 22.39 | S96: 27.73
A97: II-5CIMANGGIS | B97: II-5 | C97: CIMANGGIS | D97: region1 | E97: 92 | F97: I-5 | G97: ASAHIMAS MRS | H97: UP2B DKI Jakarta & Banten | I97: 150 | J97: 0.0014 | K97: 0.0146 | L97: 0 | M97: 0.01 | N97: 0.00524 | O97: 0.02533 | P97: 22.81 | Q97: 28.71 | R97: 22.39 | S97: 27.73
... A101: II-5CITRA HABITAT | B101: II-5 | C101: CITRA HABITAT | D101: region1 | E101: 96 | F101: I-5 | G101: BAYAH5 | H101: UP2B DKI Jakarta & Banten | I101: 150 | J101: 0.0078 | K101: 0.0533 | L101: 0.01 | M101: 0.05 | N101: 0.0446 | O101: 0.16792 | P101: 4.52 | Q101: 7.86 | R101: 4.43 | S101: 7.46
A102: I-5CSW | B102: I-5 | C102: CSW | D102: region1 | E102: 97 | F102: IV | G102: BEKASI | H102: UP2B DKI Jakarta & Banten | I102: 150 | J102: 0.0007 | K102: 0.0155 | L102: 0 | M102: 0.02 | N102: 0.00056 | O102: 0.00902 | P102: 31.58 | Q102: 27.23 | R102: 30.63 | S102: 26.18 | V102: 225 | W102: =$V102*J102 -> 0.1575 | X102: =$V102*K102 -> 3.4875 | Y102: =$V102*L102 -> 0 | Z102: =$V102*M102 -> 4.5 | AA102: =$V102*N102 -> 0.126 | AB102: =$V102*O102 -> 2.0295 | AC102: =(W102^2+X102^2)^0.5 -> 3.4910546 | AD102: =(Y102^2+Z102^2)^0.5 -> 4.5 | AE102: =(AB102^2+AA102^2)^0.5 -> 2.0334075 | AF102: 0.5 | AG102: =AC102/AF102 -> 6.9821093
A103: II-5CSW | B103: II-5 | C103: CSW | D103: region1 | E103: 98 | F103: III | G103: BEKASI | H103: UP2B DKI Jakarta & Banten | I103: 150 | J103: 0.0007 | K103: 0.0155 | L103: 0 | M103: 0.02 | N103: 0.00056 | O103: 0.00902 | P103: 31.58 | Q103: 27.23 | R103: 30.63 | S103: 26.18 | V103: 225 | W103: =$V103*J103 -> 0.1575 | X103: =$V103*K103 -> 3.4875 | Y103: =$V103*L103 -> 0 | Z103: =$V103*M103 -> 4.5 | AA103: =$V103*N103 -> 0.126 | AB103: =$V103*O103 -> 2.0295 | AC103: =(W103^2+X103^2)^0.5 -> 3.4910546 | AD103: =(Y103^2+Z103^2)^0.5 -> 4.5 | AE103: =(AB103^2+AA103^2)^0.5 -> 2.0334075 | AF103: 0.5 | AG103: =AC103/AF103 -> 6.9821093
A104: I-5CURUG | B104: I-5 | C104: CURUG | D104: region1 | E104: 99 | F104: II-5 | G104: BEKASI | H104: UP2B DKI Jakarta & Banten | I104: 150 | J104: 0.0009 | K104: 0.0102 | L104: 0 | M104: 0.01 | N104: 0.00065 | O104: 0.00915 | P104: 42.4 | Q104: 41.36 | R104: 40.87 | S104: 39.25 | V104: 225 | W104: =$V104*J104 -> 0.2025 | X104: =$V104*K104 -> 2.295 | Y104: =$V104*L104 -> 0 | Z104: =$V104*M104 -> 2.25 | AA104: =$V104*N104 -> 0.14625 | AB104: =$V104*O104 -> 2.05875 | AC104: =(W104^2+X104^2)^0.5 -> 2.3039165 | AD104: =(Y104^2+Z104^2)^0.5 -> 2.25 | AE104: =(AB104^2+AA104^2)^0.5 -> 2.0639381 | AF104: 0.5 | AG104: =AC104/AF104 -> 4.607833
A105: II-5CURUG | B105: II-5 | C105: CURUG | D105: region1 | E105: 100 | F105: I-5 | G105: BEKASI | H105: UP2B DKI Jakarta & Banten | I105: 150 | J105: 0.0011 | K105: 0.0123 | L105: 0 | M105: 0.01 | N105: 0.00057 | O105: 0.0102 | P105: 35.94 | Q105: 34.05 | R105: 34.87 | S105: 32.65 | V105: 225 | W105: =$V105*J105 -> 0.2475 | X105: =$V105*K105 -> 2.7675 | Y105: =$V105*L105 -> 0 | Z105: =$V105*M105 -> 2.25 | AA105: =$V105*N105 -> 0.12825 | AB105: =$V105*O105 -> 2.295 | AC105: =(W105^2+X105^2)^0.5 -> 2.778545 | AD105: =(Y105^2+Z105^2)^0.5 -> 2.25 | AE105: =(AB105^2+AA105^2)^0.5 -> 2.2985807 | AF105: 0.5 | AG105: =AC105/AF105 -> 5.5570901
A106: I-5DAAN MOGOT | B106: I-5 | C106: DAAN MOGOT | D106: region1 | E106: 101 | F106: 5-II | G106: BEKASI 2 | H106: UP2B DKI Jakarta & Banten | I106: 150 | J106: 0.0007 | K106: 0.0164 | L106: 0 | M106: 0.02 | N106: 0.00202 | O106: 0.01272 | P106: 27.75 | Q106: 25.8 | R106: 27.02 | S106: 24.86
A107: II-5DAAN MOGOT | B107: II-5 | C107: DAAN MOGOT | D107: region1 | E107: 102 | F107: 5-I | G107: BEKASI 2 | H107: UP2B DKI Jakarta & Banten | I107: 150 | J107: 0.0007 | K107: 0.0164 | L107: 0 | M107: 0.02 | N107: 0.00202 | O107: 0.01272 | P107: 27.75 | Q107: 25.8 | R107: 27.02 | S107: 24.86
A108: IDANAYASA | B108: I | C108: DANAYASA | D108: region1 | E108: 103 | F108: II-5 | G108: BINTARO | H108: UP2B DKI Jakarta & Banten | I108: 150 | J108: 0.0018 | K108: 0.0181 | L108: 0 | M108: 0.02 | N108: 0.0043 | O108: 0.02331 | P108: 21.1 | Q108: 23.21 | R108: 20.77 | S108: 22.61
A109: IIDANAYASA | B109: II | C109: DANAYASA | D109: region1 | E109: 104 | F109: I-5 | G109: BINTARO | H109: UP2B DKI Jakarta & Banten | I109: 150 | J109: 0.0018 | K109: 0.0181 | L109: 0 | M109: 0.02 | N109: 0.0043 | O109: 0.02331 | P109: 21.1 | Q109: 23.21 | R109: 20.77 | S109: 22.61
...

Sheet DB
B1: panjang L4 | C1: Seleksi L4 lagi | D1: Seleksi L4 | E1: Panjang | F1: ALL Kandidat L4 | G1: Kandidat L4 | H1: Kandidat L4 | I1: Panjang L2 L3 | J1: Seleksi L2 L3 lagi | K1: Seleksi L2 L3 | L1: ALL Kandidat L2,L3 | M1: Kandidat L2,L3 | N1: Kandidat L2,L3 | O1: ALL Kandidat L1 | P1: Kandidat L1 | Q1: Kandidat L1 | T1: CARA UPDATE : Digsilent 14.1 - Object (Kaca Mata) - Line (*.ElmLne) - Basic Data - Select All - Right Click -Spread Sheet Format - Copy (with Column Header) - Paste pada SEL T2 | U1: In Folder | V1: Grid | BA1: Line Couplings
T2: Name | U2: In Folder | V2: Grid | W2: Type | X2: Terminal i | Y2: Terminal i | Z2: Terminal j | AA2: Terminal j | AB2: Zone | AC2: Area | AD2: Out of Service | AE2: Par.no. | AF2: Thermal Rating | AG2: Length | AH2: Derating F. | AI2: Laying | AJ2: Line Model | AK2: Type of Phase Conductors | AL2: Type of Earth Conductors | AM2: Max.Sag, Phase Conductors | AN2: Max.Sag, Ground Wires | AO2: Earth Resistivity | AP2: Transposition | AQ2: Irated | AR2: Z1 | AS2: phiz1 | AT2: R1 | AU2: X1 | AV2: R0 | AW2: X0 | AX2: Ice | AY2: k0 | AZ2: phik0 | BA2: Line Couplings
W3: TypLne,TypTow,TypGeo | X3: Substation | Z3: Substation | AF3: IntThrating | AG3: km | AK3: TypCon | AL3: TypCon | AM3: m | AN3: m | AO3: Ohmm | AQ3: kA | AR3: Ohm | AS3: deg | AT3: Ohm | AU3: Ohm | AV3: Ohm | AW3: Ohm | AX3: A | AZ3: deg
D4: =counta(D5:D1529) -> 2 | F4: =counta(F5:F1529) -> 3 | K4: =counta(K5:K1529) -> 3 | L4: =counta(L5:L1529) -> 4 | T4: 1MENES-1LBUAN-1 | U4: region1 | V4: region1 | W4: OHL-150kV-TACSR 2X410mm (2730A) | X4: MENES5 | Y4: I-5 | Z4: PLTU Banten 2 | AA4: I | AD4: 0 | AE4: 1 | AG4: 6.2 | AH4: 1 | AI4: Ground | AJ4: 0 | AM4: 0 | AN4: 0 | AO4: 100 | AP4: 1 | AQ4: 2.73 | AR4: 1.647643 | AS4: 76.21999 | AT4: 0.39246 | AU4: 1.60022 | AV4: 1.32246 | AW4: 4.80066 | AX4: 0 | AY4: 0.6742607 | AZ4: -2.423059
A5: =COUNTA(C5:Q5)-1 -> 6 | B5: =if(C5="",,AR5) -> 1.647643 | C5: =if(and(D$4>1,E5=PROSES!$D$22),,D5) -> 1MENES-1LBUAN-2 | D5: =if(and(F$4>1,F5=PROSES!$B$22),,F5) -> 1MENES-1LBUAN-2 | E5: =if(F5="",,AR5) -> 1.647643 | F5: =if(G5=H5,,(G5&H5)) -> 1MENES-1LBUAN-2 | G5: =if(Z5=PROSES!$E$29,T5,) | H5: =if(X5=PROSES!$E$29,T5,) -> 1MENES-1LBUAN-2 | I5: =if(J5="",,AR5) | J5: =if(and(K$4>1,R5=PROSES!$C$2),,K5) | K5: =if(and(L$4>1,L5=PROSES!$B$2),,L5) | L5: =if(M5=N5,,(M5&N5)) | M5: =if(Z5=PROSES!$B$3,T5,) | N5: =if(X5=PROSES!$B$3,T5,) | O5: =P5&Q5 -> 1MENES-1LBUAN-2 | P5: =if(Z5=PROSES!$B$1,T5,) | Q5: =if(X5=PROSES!$B$1,T5,) -> 1MENES-1LBUAN-2 | R5: =X5&Z5 -> MENES5PLTU Banten 2 | T5: 1MENES-1LBUAN-2 | U5: region1 | V5: region1 | W5: OHL-150kV-TACSR 2X410mm (2730A) | X5: MENES5 | Y5: II-5 | Z5: PLTU Banten 2 | AA5: I | AD5: 0 | AE5: 1 | AG5: 6.2 | AH5: 1 | AI5: Ground | AJ5: 0 | AM5: 0 | AN5: 0 | AO5: 100 | AP5: 1 | AQ5: 2.73 | AR5: 1.647643 | AS5: 76.21999 | AT5: 0.39246 | AU5: 1.60022 | AV5: 1.32246 | AW5: 4.80066 | AX5: 0 | AY5: 0.6742607 | AZ5: -2.423059
